{
  "nbformat": 4,
  "nbformat_minor": 0,
  "metadata": {
    "colab": {
      "provenance": [],
      "gpuType": "T4",
      "authorship_tag": "ABX9TyOJ2bODIolfP7rCvzyhg022",
      "include_colab_link": true
    },
    "kernelspec": {
      "name": "python3",
      "display_name": "Python 3"
    },
    "language_info": {
      "name": "python"
    },
    "accelerator": "GPU"
  },
  "cells": [
    {
      "cell_type": "markdown",
      "metadata": {
        "id": "view-in-github",
        "colab_type": "text"
      },
      "source": [
        "<a href=\"https://colab.research.google.com/github/Vadim-sys-create/TTS/blob/main/_untitled19_ipynb.ipynb\" target=\"_parent\"><img src=\"https://colab.research.google.com/assets/colab-badge.svg\" alt=\"Open In Colab\"/></a>"
      ]
    },
    {
      "cell_type": "code",
      "source": [
        "!pip install gtts"
      ],
      "metadata": {
        "colab": {
          "base_uri": "https://localhost:8080/"
        },
        "id": "mpzv7lhON81i",
        "outputId": "48581959-676a-4ebd-a785-6d71a2d56a02"
      },
      "execution_count": null,
      "outputs": [
        {
          "output_type": "stream",
          "name": "stdout",
          "text": [
            "Requirement already satisfied: gtts in /usr/local/lib/python3.11/dist-packages (2.5.4)\n",
            "Requirement already satisfied: requests<3,>=2.27 in /usr/local/lib/python3.11/dist-packages (from gtts) (2.32.3)\n",
            "Requirement already satisfied: click<8.2,>=7.1 in /usr/local/lib/python3.11/dist-packages (from gtts) (8.1.8)\n",
            "Requirement already satisfied: charset-normalizer<4,>=2 in /usr/local/lib/python3.11/dist-packages (from requests<3,>=2.27->gtts) (3.4.1)\n",
            "Requirement already satisfied: idna<4,>=2.5 in /usr/local/lib/python3.11/dist-packages (from requests<3,>=2.27->gtts) (3.10)\n",
            "Requirement already satisfied: urllib3<3,>=1.21.1 in /usr/local/lib/python3.11/dist-packages (from requests<3,>=2.27->gtts) (2.3.0)\n",
            "Requirement already satisfied: certifi>=2017.4.17 in /usr/local/lib/python3.11/dist-packages (from requests<3,>=2.27->gtts) (2025.1.31)\n"
          ]
        }
      ]
    },
    {
      "cell_type": "code",
      "source": [
        "!pip install --force-reinstall gtts"
      ],
      "metadata": {
        "colab": {
          "base_uri": "https://localhost:8080/",
          "height": 998
        },
        "id": "iU2LUOEKRPLt",
        "outputId": "9a428791-0de1-4939-fa92-37d88061ab2e"
      },
      "execution_count": null,
      "outputs": [
        {
          "output_type": "stream",
          "name": "stdout",
          "text": [
            "Collecting gtts\n",
            "  Using cached gTTS-2.5.4-py3-none-any.whl.metadata (4.1 kB)\n",
            "Collecting requests<3,>=2.27 (from gtts)\n",
            "  Using cached requests-2.32.3-py3-none-any.whl.metadata (4.6 kB)\n",
            "Collecting click<8.2,>=7.1 (from gtts)\n",
            "  Using cached click-8.1.8-py3-none-any.whl.metadata (2.3 kB)\n",
            "Collecting charset-normalizer<4,>=2 (from requests<3,>=2.27->gtts)\n",
            "  Using cached charset_normalizer-3.4.1-cp311-cp311-manylinux_2_17_x86_64.manylinux2014_x86_64.whl.metadata (35 kB)\n",
            "Collecting idna<4,>=2.5 (from requests<3,>=2.27->gtts)\n",
            "  Using cached idna-3.10-py3-none-any.whl.metadata (10 kB)\n",
            "Collecting urllib3<3,>=1.21.1 (from requests<3,>=2.27->gtts)\n",
            "  Using cached urllib3-2.3.0-py3-none-any.whl.metadata (6.5 kB)\n",
            "Collecting certifi>=2017.4.17 (from requests<3,>=2.27->gtts)\n",
            "  Using cached certifi-2025.1.31-py3-none-any.whl.metadata (2.5 kB)\n",
            "Using cached gTTS-2.5.4-py3-none-any.whl (29 kB)\n",
            "Using cached click-8.1.8-py3-none-any.whl (98 kB)\n",
            "Using cached requests-2.32.3-py3-none-any.whl (64 kB)\n",
            "Using cached certifi-2025.1.31-py3-none-any.whl (166 kB)\n",
            "Using cached charset_normalizer-3.4.1-cp311-cp311-manylinux_2_17_x86_64.manylinux2014_x86_64.whl (143 kB)\n",
            "Using cached idna-3.10-py3-none-any.whl (70 kB)\n",
            "Using cached urllib3-2.3.0-py3-none-any.whl (128 kB)\n",
            "Installing collected packages: urllib3, idna, click, charset-normalizer, certifi, requests, gtts\n",
            "  Attempting uninstall: urllib3\n",
            "    Found existing installation: urllib3 2.3.0\n",
            "    Uninstalling urllib3-2.3.0:\n",
            "      Successfully uninstalled urllib3-2.3.0\n",
            "  Attempting uninstall: idna\n",
            "    Found existing installation: idna 3.10\n",
            "    Uninstalling idna-3.10:\n",
            "      Successfully uninstalled idna-3.10\n",
            "  Attempting uninstall: click\n",
            "    Found existing installation: click 8.1.8\n",
            "    Uninstalling click-8.1.8:\n",
            "      Successfully uninstalled click-8.1.8\n",
            "  Attempting uninstall: charset-normalizer\n",
            "    Found existing installation: charset-normalizer 3.4.1\n",
            "    Uninstalling charset-normalizer-3.4.1:\n",
            "      Successfully uninstalled charset-normalizer-3.4.1\n",
            "  Attempting uninstall: certifi\n",
            "    Found existing installation: certifi 2025.1.31\n",
            "    Uninstalling certifi-2025.1.31:\n",
            "      Successfully uninstalled certifi-2025.1.31\n",
            "  Attempting uninstall: requests\n",
            "    Found existing installation: requests 2.32.3\n",
            "    Uninstalling requests-2.32.3:\n",
            "      Successfully uninstalled requests-2.32.3\n",
            "  Attempting uninstall: gtts\n",
            "    Found existing installation: gTTS 2.5.4\n",
            "    Uninstalling gTTS-2.5.4:\n",
            "      Successfully uninstalled gTTS-2.5.4\n",
            "Successfully installed certifi-2025.1.31 charset-normalizer-3.4.1 click-8.1.8 gtts-2.5.4 idna-3.10 requests-2.32.3 urllib3-2.3.0\n"
          ]
        },
        {
          "output_type": "display_data",
          "data": {
            "application/vnd.colab-display-data+json": {
              "pip_warning": {
                "packages": [
                  "certifi"
                ]
              },
              "id": "4cdd3bc35c084ebba3994b35e08e091f"
            }
          },
          "metadata": {}
        }
      ]
    },
    {
      "cell_type": "code",
      "source": [
        "text = \"Привет, это тестовое аудио.\""
      ],
      "metadata": {
        "id": "GNJZ1ow4PYS3"
      },
      "execution_count": null,
      "outputs": []
    },
    {
      "cell_type": "code",
      "source": [
        "# Установка библиотек\n",
        "!pip install aiogram transformers gtts fuzzywuzzy langdetect nest_asyncio\n",
        "\n",
        "# Импорт библиотек\n",
        "import os\n",
        "from aiogram import Bot, Dispatcher, types\n",
        "from aiogram.filters import Command\n",
        "from aiogram.enums import ParseMode\n",
        "from aiogram.client.default import DefaultBotProperties\n",
        "from transformers import GPT2LMHeadModel, GPT2Tokenizer\n",
        "from gtts import gTTS\n",
        "from fuzzywuzzy import process\n",
        "from langdetect import detect\n",
        "import nest_asyncio\n",
        "\n",
        "# Применяем nest_asyncio для работы в Colab\n",
        "nest_asyncio.apply()\n",
        "\n",
        "# Загрузка модели и токенизатора\n",
        "model_name = \"sberbank-ai/rugpt3large_based_on_gpt2\"\n",
        "tokenizer = GPT2Tokenizer.from_pretrained(model_name)\n",
        "model = GPT2LMHeadModel.from_pretrained(model_name)\n",
        "\n",
        "# Ваши ответы на вопросы\n",
        "my_responses = {\n",
        "    \"Как тебя зовут?\": \"Меня зовут Аватар, и я здесь, чтобы помочь тебе!\",\n",
        "    \"What is your name?\": \"My name is Avatar, and I'm here to help you!\",\n",
        "    \"¿Cómo te llamas?\": \"Me llamo Avatar, y estoy aquí para ayudarte.\",\n",
        "    \"Comment tu t'appelles?\": \"Je m'appelle Avatar, et je suis là pour vous aider.\",\n",
        "}\n",
        "\n",
        "# Функция для генерации ответа\n",
        "def generate_response(question, max_length=50):\n",
        "    # Поиск наиболее похожего вопроса в словаре\n",
        "    match, score = process.extractOne(question, my_responses.keys())\n",
        "\n",
        "    # Если совпадение достаточно точное (например, score > 80), возвращаем ответ\n",
        "    if score > 80:\n",
        "        return my_responses[match]\n",
        "\n",
        "    # Если совпадение неточное, генерируем ответ с помощью модели\n",
        "    inputs = tokenizer(question, return_tensors=\"pt\")\n",
        "    outputs = model.generate(\n",
        "        inputs[\"input_ids\"],\n",
        "        max_length=max_length,\n",
        "        num_return_sequences=1,\n",
        "        no_repeat_ngram_size=2,\n",
        "        top_k=50,\n",
        "        top_p=0.95,\n",
        "        temperature=0.7,\n",
        "    )\n",
        "    return tokenizer.decode(outputs[0], skip_special_tokens=True)\n",
        "\n",
        "# Функция для определения языка текста\n",
        "def detect_language(text):\n",
        "    try:\n",
        "        return detect(text)\n",
        "    except:\n",
        "        return 'ru'  # По умолчанию используем русский язык\n",
        "\n",
        "# Функция для создания аудио из текста\n",
        "def create_audio_from_text(text, output_file=\"response.mp3\"):\n",
        "    lang = detect_language(text)  # Автоматически определяем язык\n",
        "    tts = gTTS(text, lang=lang)\n",
        "    tts.save(output_file)\n",
        "    return output_file\n",
        "\n",
        "# Инициализация бота\n",
        "API_TOKEN = '7954916275:AAEoTnpSPG_DRajIGC859AqOmVejyrn7VL0'  # Замените на ваш токен\n",
        "bot = Bot(token=API_TOKEN, default=DefaultBotProperties(parse_mode=ParseMode.HTML))\n",
        "dp = Dispatcher()\n",
        "\n",
        "# Гифки и картинки для ответов\n",
        "happy_gif = \"https://media.giphy.com/media/3o7aTskHEUdgCQAXde/giphy.gif\"  # Пример гифки\n",
        "thinking_image = \"https://example.com/thinking.jpg\"  # Пример картинки\n",
        "\n",
        "# Обработчик команды /start\n",
        "@dp.message(Command(\"start\"))\n",
        "async def send_welcome(message: types.Message):\n",
        "    await message.answer(\"Привет! Я Аватар. Задай мне вопрос!\")\n",
        "    await message.answer_animation(happy_gif)  # Отправляем гифку\n",
        "\n",
        "# Обработчик текстовых сообщений\n",
        "@dp.message()\n",
        "async def echo(message: types.Message):\n",
        "    user_input = message.text\n",
        "\n",
        "    if user_input.lower() in [\"выход\", \"exit\", \"quit\"]:\n",
        "        await message.answer(\"Аватар: Пока!\")\n",
        "        return\n",
        "\n",
        "    try:\n",
        "        # Генерация ответа\n",
        "        response = generate_response(user_input)\n",
        "        await message.answer(f\"Аватар: {response}\")\n",
        "\n",
        "        # Создание аудио\n",
        "        audio_file = create_audio_from_text(response)\n",
        "\n",
        "        # Проверка, создан ли аудиофайл\n",
        "        if os.path.exists(audio_file):\n",
        "            print(\"Аудиофайл создан.\")  # Для отладки\n",
        "\n",
        "            # Отправка аудио (используем путь к файлу)\n",
        "            with open(audio_file, \"rb\") as audio:\n",
        "                await message.answer_audio(audio)\n",
        "        else:\n",
        "            print(\"Ошибка: аудиофайл не создан.\")  # Для отладки\n",
        "            await message.answer(\"Не удалось создать аудио.\")\n",
        "\n",
        "        # Отправка гифки или картинки\n",
        "        if \"радост\" in response.lower():\n",
        "            await message.answer_animation(happy_gif)  # Отправляем гифку\n",
        "        else:\n",
        "            await message.answer_photo(thinking_image)  # Отправляем картинку\n",
        "\n",
        "        # Удаление временного файла\n",
        "        if os.path.exists(audio_file):\n",
        "            os.remove(audio_file)\n",
        "    except Exception as e:\n",
        "        await message.answer(f\"Произошла ошибка: {str(e)}\")  # Исправлено: str(e) для корректного вывода ошибки\n",
        "\n",
        "# Запуск бота\n",
        "async def start_bot():\n",
        "    await dp.start_polling(bot)\n",
        "\n",
        "# Запуск бота в Colab\n",
        "await start_bot()"
      ],
      "metadata": {
        "colab": {
          "base_uri": "https://localhost:8080/"
        },
        "id": "Vau73KauV78s",
        "outputId": "7ad858d6-eefd-447d-c42f-7df31e35771d"
      },
      "execution_count": null,
      "outputs": [
        {
          "output_type": "stream",
          "name": "stdout",
          "text": [
            "Requirement already satisfied: aiogram in /usr/local/lib/python3.11/dist-packages (3.18.0)\n",
            "Requirement already satisfied: transformers in /usr/local/lib/python3.11/dist-packages (4.47.1)\n",
            "Requirement already satisfied: gtts in /usr/local/lib/python3.11/dist-packages (2.5.4)\n",
            "Requirement already satisfied: fuzzywuzzy in /usr/local/lib/python3.11/dist-packages (0.18.0)\n",
            "Requirement already satisfied: langdetect in /usr/local/lib/python3.11/dist-packages (1.0.9)\n",
            "Requirement already satisfied: nest_asyncio in /usr/local/lib/python3.11/dist-packages (1.6.0)\n",
            "Requirement already satisfied: aiofiles<24.2,>=23.2.1 in /usr/local/lib/python3.11/dist-packages (from aiogram) (24.1.0)\n",
            "Requirement already satisfied: aiohttp<3.12,>=3.9.0 in /usr/local/lib/python3.11/dist-packages (from aiogram) (3.11.11)\n",
            "Requirement already satisfied: certifi>=2023.7.22 in /usr/local/lib/python3.11/dist-packages (from aiogram) (2024.12.14)\n",
            "Requirement already satisfied: magic-filter<1.1,>=1.0.12 in /usr/local/lib/python3.11/dist-packages (from aiogram) (1.0.12)\n",
            "Requirement already satisfied: pydantic<2.11,>=2.4.1 in /usr/local/lib/python3.11/dist-packages (from aiogram) (2.10.6)\n",
            "Requirement already satisfied: typing-extensions<=5.0,>=4.7.0 in /usr/local/lib/python3.11/dist-packages (from aiogram) (4.12.2)\n",
            "Requirement already satisfied: filelock in /usr/local/lib/python3.11/dist-packages (from transformers) (3.17.0)\n",
            "Requirement already satisfied: huggingface-hub<1.0,>=0.24.0 in /usr/local/lib/python3.11/dist-packages (from transformers) (0.27.1)\n",
            "Requirement already satisfied: numpy>=1.17 in /usr/local/lib/python3.11/dist-packages (from transformers) (1.26.4)\n",
            "Requirement already satisfied: packaging>=20.0 in /usr/local/lib/python3.11/dist-packages (from transformers) (24.2)\n",
            "Requirement already satisfied: pyyaml>=5.1 in /usr/local/lib/python3.11/dist-packages (from transformers) (6.0.2)\n",
            "Requirement already satisfied: regex!=2019.12.17 in /usr/local/lib/python3.11/dist-packages (from transformers) (2024.11.6)\n",
            "Requirement already satisfied: requests in /usr/local/lib/python3.11/dist-packages (from transformers) (2.32.3)\n",
            "Requirement already satisfied: tokenizers<0.22,>=0.21 in /usr/local/lib/python3.11/dist-packages (from transformers) (0.21.0)\n",
            "Requirement already satisfied: safetensors>=0.4.1 in /usr/local/lib/python3.11/dist-packages (from transformers) (0.5.2)\n",
            "Requirement already satisfied: tqdm>=4.27 in /usr/local/lib/python3.11/dist-packages (from transformers) (4.67.1)\n",
            "Requirement already satisfied: click<8.2,>=7.1 in /usr/local/lib/python3.11/dist-packages (from gtts) (8.1.8)\n",
            "Requirement already satisfied: six in /usr/local/lib/python3.11/dist-packages (from langdetect) (1.17.0)\n",
            "Requirement already satisfied: aiohappyeyeballs>=2.3.0 in /usr/local/lib/python3.11/dist-packages (from aiohttp<3.12,>=3.9.0->aiogram) (2.4.4)\n",
            "Requirement already satisfied: aiosignal>=1.1.2 in /usr/local/lib/python3.11/dist-packages (from aiohttp<3.12,>=3.9.0->aiogram) (1.3.2)\n",
            "Requirement already satisfied: attrs>=17.3.0 in /usr/local/lib/python3.11/dist-packages (from aiohttp<3.12,>=3.9.0->aiogram) (24.3.0)\n",
            "Requirement already satisfied: frozenlist>=1.1.1 in /usr/local/lib/python3.11/dist-packages (from aiohttp<3.12,>=3.9.0->aiogram) (1.5.0)\n",
            "Requirement already satisfied: multidict<7.0,>=4.5 in /usr/local/lib/python3.11/dist-packages (from aiohttp<3.12,>=3.9.0->aiogram) (6.1.0)\n",
            "Requirement already satisfied: propcache>=0.2.0 in /usr/local/lib/python3.11/dist-packages (from aiohttp<3.12,>=3.9.0->aiogram) (0.2.1)\n",
            "Requirement already satisfied: yarl<2.0,>=1.17.0 in /usr/local/lib/python3.11/dist-packages (from aiohttp<3.12,>=3.9.0->aiogram) (1.18.3)\n",
            "Requirement already satisfied: fsspec>=2023.5.0 in /usr/local/lib/python3.11/dist-packages (from huggingface-hub<1.0,>=0.24.0->transformers) (2024.10.0)\n",
            "Requirement already satisfied: annotated-types>=0.6.0 in /usr/local/lib/python3.11/dist-packages (from pydantic<2.11,>=2.4.1->aiogram) (0.7.0)\n",
            "Requirement already satisfied: pydantic-core==2.27.2 in /usr/local/lib/python3.11/dist-packages (from pydantic<2.11,>=2.4.1->aiogram) (2.27.2)\n",
            "Requirement already satisfied: charset-normalizer<4,>=2 in /usr/local/lib/python3.11/dist-packages (from requests->transformers) (3.4.1)\n",
            "Requirement already satisfied: idna<4,>=2.5 in /usr/local/lib/python3.11/dist-packages (from requests->transformers) (3.10)\n",
            "Requirement already satisfied: urllib3<3,>=1.21.1 in /usr/local/lib/python3.11/dist-packages (from requests->transformers) (2.3.0)\n"
          ]
        },
        {
          "output_type": "stream",
          "name": "stderr",
          "text": [
            "ERROR:aiogram.event:Cause exception while process update id=995587221 by bot id=7954916275\n",
            "TelegramBadRequest: Telegram server says - Bad Request: can't parse entities: Unsupported start tag \"_io.bufferedreader\" at byte offset 173\n",
            "Traceback (most recent call last):\n",
            "  File \"<ipython-input-6-d12a11f58cce>\", line 106, in echo\n",
            "    await message.answer_audio(audio)\n",
            "          ^^^^^^^^^^^^^^^^^^^^^^^^^^^\n",
            "  File \"/usr/local/lib/python3.11/dist-packages/aiogram/types/message.py\", line 1022, in answer_audio\n",
            "    return SendAudio(\n",
            "           ^^^^^^^^^^\n",
            "  File \"/usr/local/lib/python3.11/dist-packages/pydantic/main.py\", line 214, in __init__\n",
            "    validated_self = self.__pydantic_validator__.validate_python(data, self_instance=self)\n",
            "                     ^^^^^^^^^^^^^^^^^^^^^^^^^^^^^^^^^^^^^^^^^^^^^^^^^^^^^^^^^^^^^^^^^^^^^\n",
            "pydantic_core._pydantic_core.ValidationError: 2 validation errors for SendAudio\n",
            "audio.is-instance[InputFile]\n",
            "  Input should be an instance of InputFile [type=is_instance_of, input_value=<_io.BufferedReader name='response.mp3'>, input_type=BufferedReader]\n",
            "    For further information visit https://errors.pydantic.dev/2.10/v/is_instance_of\n",
            "audio.str\n",
            "  Input should be a valid string [type=string_type, input_value=<_io.BufferedReader name='response.mp3'>, input_type=BufferedReader]\n",
            "    For further information visit https://errors.pydantic.dev/2.10/v/string_type\n",
            "\n",
            "During handling of the above exception, another exception occurred:\n",
            "\n",
            "Traceback (most recent call last):\n",
            "  File \"/usr/local/lib/python3.11/dist-packages/aiogram/dispatcher/dispatcher.py\", line 309, in _process_update\n",
            "    response = await self.feed_update(bot, update, **kwargs)\n",
            "               ^^^^^^^^^^^^^^^^^^^^^^^^^^^^^^^^^^^^^^^^^^^^^\n",
            "  File \"/usr/local/lib/python3.11/dist-packages/aiogram/dispatcher/dispatcher.py\", line 158, in feed_update\n",
            "    response = await self.update.wrap_outer_middleware(\n",
            "               ^^^^^^^^^^^^^^^^^^^^^^^^^^^^^^^^^^^^^^^^\n",
            "  File \"/usr/local/lib/python3.11/dist-packages/aiogram/dispatcher/middlewares/error.py\", line 25, in __call__\n",
            "    return await handler(event, data)\n",
            "           ^^^^^^^^^^^^^^^^^^^^^^^^^^\n",
            "  File \"/usr/local/lib/python3.11/dist-packages/aiogram/dispatcher/middlewares/user_context.py\", line 56, in __call__\n",
            "    return await handler(event, data)\n",
            "           ^^^^^^^^^^^^^^^^^^^^^^^^^^\n",
            "  File \"/usr/local/lib/python3.11/dist-packages/aiogram/fsm/middleware.py\", line 42, in __call__\n",
            "    return await handler(event, data)\n",
            "           ^^^^^^^^^^^^^^^^^^^^^^^^^^\n",
            "  File \"/usr/local/lib/python3.11/dist-packages/aiogram/dispatcher/event/telegram.py\", line 121, in trigger\n",
            "    return await wrapped_inner(event, kwargs)\n",
            "           ^^^^^^^^^^^^^^^^^^^^^^^^^^^^^^^^^^\n",
            "  File \"/usr/local/lib/python3.11/dist-packages/aiogram/dispatcher/event/handler.py\", line 43, in call\n",
            "    return await wrapped()\n",
            "           ^^^^^^^^^^^^^^^\n",
            "  File \"/usr/local/lib/python3.11/dist-packages/aiogram/dispatcher/dispatcher.py\", line 276, in _listen_update\n",
            "    return await self.propagate_event(update_type=update_type, event=event, **kwargs)\n",
            "           ^^^^^^^^^^^^^^^^^^^^^^^^^^^^^^^^^^^^^^^^^^^^^^^^^^^^^^^^^^^^^^^^^^^^^^^^^^\n",
            "  File \"/usr/local/lib/python3.11/dist-packages/aiogram/dispatcher/router.py\", line 146, in propagate_event\n",
            "    return await observer.wrap_outer_middleware(_wrapped, event=event, data=kwargs)\n",
            "           ^^^^^^^^^^^^^^^^^^^^^^^^^^^^^^^^^^^^^^^^^^^^^^^^^^^^^^^^^^^^^^^^^^^^^^^^\n",
            "  File \"/usr/local/lib/python3.11/dist-packages/aiogram/dispatcher/router.py\", line 141, in _wrapped\n",
            "    return await self._propagate_event(\n",
            "           ^^^^^^^^^^^^^^^^^^^^^^^^^^^^\n",
            "  File \"/usr/local/lib/python3.11/dist-packages/aiogram/dispatcher/router.py\", line 166, in _propagate_event\n",
            "    response = await observer.trigger(event, **kwargs)\n",
            "               ^^^^^^^^^^^^^^^^^^^^^^^^^^^^^^^^^^^^^^^\n",
            "  File \"/usr/local/lib/python3.11/dist-packages/aiogram/dispatcher/event/telegram.py\", line 121, in trigger\n",
            "    return await wrapped_inner(event, kwargs)\n",
            "           ^^^^^^^^^^^^^^^^^^^^^^^^^^^^^^^^^^\n",
            "  File \"/usr/local/lib/python3.11/dist-packages/aiogram/dispatcher/event/handler.py\", line 43, in call\n",
            "    return await wrapped()\n",
            "           ^^^^^^^^^^^^^^^\n",
            "  File \"<ipython-input-6-d12a11f58cce>\", line 121, in echo\n",
            "    await message.answer(f\"Произошла ошибка: {str(e)}\")  # Исправлено: str(e) для корректного вывода ошибки\n",
            "    ^^^^^^^^^^^^^^^^^^^^^^^^^^^^^^^^^^^^^^^^^^^^^^^^^^^\n",
            "  File \"/usr/local/lib/python3.11/dist-packages/aiogram/methods/base.py\", line 84, in emit\n",
            "    return await bot(self)\n",
            "           ^^^^^^^^^^^^^^^\n",
            "  File \"/usr/local/lib/python3.11/dist-packages/aiogram/client/bot.py\", line 498, in __call__\n",
            "    return await self.session(self, method, timeout=request_timeout)\n",
            "           ^^^^^^^^^^^^^^^^^^^^^^^^^^^^^^^^^^^^^^^^^^^^^^^^^^^^^^^^^\n",
            "  File \"/usr/local/lib/python3.11/dist-packages/aiogram/client/session/base.py\", line 254, in __call__\n",
            "    return cast(TelegramType, await middleware(bot, method))\n",
            "                              ^^^^^^^^^^^^^^^^^^^^^^^^^^^^^\n",
            "  File \"/usr/local/lib/python3.11/dist-packages/aiogram/client/session/aiohttp.py\", line 185, in make_request\n",
            "    response = self.check_response(\n",
            "               ^^^^^^^^^^^^^^^^^^^^\n",
            "  File \"/usr/local/lib/python3.11/dist-packages/aiogram/client/session/base.py\", line 120, in check_response\n",
            "    raise TelegramBadRequest(method=method, message=description)\n",
            "aiogram.exceptions.TelegramBadRequest: Telegram server says - Bad Request: can't parse entities: Unsupported start tag \"_io.bufferedreader\" at byte offset 173\n"
          ]
        },
        {
          "output_type": "stream",
          "name": "stdout",
          "text": [
            "Аудиофайл создан.\n"
          ]
        },
        {
          "output_type": "stream",
          "name": "stderr",
          "text": [
            "WARNING:root:Applied processor reduces input query to empty string, all comparisons will have score 0. [Query: '😀']\n",
            "/usr/local/lib/python3.11/dist-packages/transformers/generation/configuration_utils.py:628: UserWarning: `do_sample` is set to `False`. However, `temperature` is set to `0.7` -- this flag is only used in sample-based generation modes. You should set `do_sample=True` or unset `temperature`.\n",
            "  warnings.warn(\n",
            "/usr/local/lib/python3.11/dist-packages/transformers/generation/configuration_utils.py:633: UserWarning: `do_sample` is set to `False`. However, `top_p` is set to `0.95` -- this flag is only used in sample-based generation modes. You should set `do_sample=True` or unset `top_p`.\n",
            "  warnings.warn(\n",
            "ERROR:aiogram.event:Cause exception while process update id=995587222 by bot id=7954916275\n",
            "TelegramBadRequest: Telegram server says - Bad Request: can't parse entities: Unsupported start tag \"_io.bufferedreader\" at byte offset 173\n",
            "Traceback (most recent call last):\n",
            "  File \"<ipython-input-6-d12a11f58cce>\", line 106, in echo\n",
            "    await message.answer_audio(audio)\n",
            "          ^^^^^^^^^^^^^^^^^^^^^^^^^^^\n",
            "  File \"/usr/local/lib/python3.11/dist-packages/aiogram/types/message.py\", line 1022, in answer_audio\n",
            "    return SendAudio(\n",
            "           ^^^^^^^^^^\n",
            "  File \"/usr/local/lib/python3.11/dist-packages/pydantic/main.py\", line 214, in __init__\n",
            "    validated_self = self.__pydantic_validator__.validate_python(data, self_instance=self)\n",
            "                     ^^^^^^^^^^^^^^^^^^^^^^^^^^^^^^^^^^^^^^^^^^^^^^^^^^^^^^^^^^^^^^^^^^^^^\n",
            "pydantic_core._pydantic_core.ValidationError: 2 validation errors for SendAudio\n",
            "audio.is-instance[InputFile]\n",
            "  Input should be an instance of InputFile [type=is_instance_of, input_value=<_io.BufferedReader name='response.mp3'>, input_type=BufferedReader]\n",
            "    For further information visit https://errors.pydantic.dev/2.10/v/is_instance_of\n",
            "audio.str\n",
            "  Input should be a valid string [type=string_type, input_value=<_io.BufferedReader name='response.mp3'>, input_type=BufferedReader]\n",
            "    For further information visit https://errors.pydantic.dev/2.10/v/string_type\n",
            "\n",
            "During handling of the above exception, another exception occurred:\n",
            "\n",
            "Traceback (most recent call last):\n",
            "  File \"/usr/local/lib/python3.11/dist-packages/aiogram/dispatcher/dispatcher.py\", line 309, in _process_update\n",
            "    response = await self.feed_update(bot, update, **kwargs)\n",
            "               ^^^^^^^^^^^^^^^^^^^^^^^^^^^^^^^^^^^^^^^^^^^^^\n",
            "  File \"/usr/local/lib/python3.11/dist-packages/aiogram/dispatcher/dispatcher.py\", line 158, in feed_update\n",
            "    response = await self.update.wrap_outer_middleware(\n",
            "               ^^^^^^^^^^^^^^^^^^^^^^^^^^^^^^^^^^^^^^^^\n",
            "  File \"/usr/local/lib/python3.11/dist-packages/aiogram/dispatcher/middlewares/error.py\", line 25, in __call__\n",
            "    return await handler(event, data)\n",
            "           ^^^^^^^^^^^^^^^^^^^^^^^^^^\n",
            "  File \"/usr/local/lib/python3.11/dist-packages/aiogram/dispatcher/middlewares/user_context.py\", line 56, in __call__\n",
            "    return await handler(event, data)\n",
            "           ^^^^^^^^^^^^^^^^^^^^^^^^^^\n",
            "  File \"/usr/local/lib/python3.11/dist-packages/aiogram/fsm/middleware.py\", line 42, in __call__\n",
            "    return await handler(event, data)\n",
            "           ^^^^^^^^^^^^^^^^^^^^^^^^^^\n",
            "  File \"/usr/local/lib/python3.11/dist-packages/aiogram/dispatcher/event/telegram.py\", line 121, in trigger\n",
            "    return await wrapped_inner(event, kwargs)\n",
            "           ^^^^^^^^^^^^^^^^^^^^^^^^^^^^^^^^^^\n",
            "  File \"/usr/local/lib/python3.11/dist-packages/aiogram/dispatcher/event/handler.py\", line 43, in call\n",
            "    return await wrapped()\n",
            "           ^^^^^^^^^^^^^^^\n",
            "  File \"/usr/local/lib/python3.11/dist-packages/aiogram/dispatcher/dispatcher.py\", line 276, in _listen_update\n",
            "    return await self.propagate_event(update_type=update_type, event=event, **kwargs)\n",
            "           ^^^^^^^^^^^^^^^^^^^^^^^^^^^^^^^^^^^^^^^^^^^^^^^^^^^^^^^^^^^^^^^^^^^^^^^^^^\n",
            "  File \"/usr/local/lib/python3.11/dist-packages/aiogram/dispatcher/router.py\", line 146, in propagate_event\n",
            "    return await observer.wrap_outer_middleware(_wrapped, event=event, data=kwargs)\n",
            "           ^^^^^^^^^^^^^^^^^^^^^^^^^^^^^^^^^^^^^^^^^^^^^^^^^^^^^^^^^^^^^^^^^^^^^^^^\n",
            "  File \"/usr/local/lib/python3.11/dist-packages/aiogram/dispatcher/router.py\", line 141, in _wrapped\n",
            "    return await self._propagate_event(\n",
            "           ^^^^^^^^^^^^^^^^^^^^^^^^^^^^\n",
            "  File \"/usr/local/lib/python3.11/dist-packages/aiogram/dispatcher/router.py\", line 166, in _propagate_event\n",
            "    response = await observer.trigger(event, **kwargs)\n",
            "               ^^^^^^^^^^^^^^^^^^^^^^^^^^^^^^^^^^^^^^^\n",
            "  File \"/usr/local/lib/python3.11/dist-packages/aiogram/dispatcher/event/telegram.py\", line 121, in trigger\n",
            "    return await wrapped_inner(event, kwargs)\n",
            "           ^^^^^^^^^^^^^^^^^^^^^^^^^^^^^^^^^^\n",
            "  File \"/usr/local/lib/python3.11/dist-packages/aiogram/dispatcher/event/handler.py\", line 43, in call\n",
            "    return await wrapped()\n",
            "           ^^^^^^^^^^^^^^^\n",
            "  File \"<ipython-input-6-d12a11f58cce>\", line 121, in echo\n",
            "    await message.answer(f\"Произошла ошибка: {str(e)}\")  # Исправлено: str(e) для корректного вывода ошибки\n",
            "    ^^^^^^^^^^^^^^^^^^^^^^^^^^^^^^^^^^^^^^^^^^^^^^^^^^^\n",
            "  File \"/usr/local/lib/python3.11/dist-packages/aiogram/methods/base.py\", line 84, in emit\n",
            "    return await bot(self)\n",
            "           ^^^^^^^^^^^^^^^\n",
            "  File \"/usr/local/lib/python3.11/dist-packages/aiogram/client/bot.py\", line 498, in __call__\n",
            "    return await self.session(self, method, timeout=request_timeout)\n",
            "           ^^^^^^^^^^^^^^^^^^^^^^^^^^^^^^^^^^^^^^^^^^^^^^^^^^^^^^^^^\n",
            "  File \"/usr/local/lib/python3.11/dist-packages/aiogram/client/session/base.py\", line 254, in __call__\n",
            "    return cast(TelegramType, await middleware(bot, method))\n",
            "                              ^^^^^^^^^^^^^^^^^^^^^^^^^^^^^\n",
            "  File \"/usr/local/lib/python3.11/dist-packages/aiogram/client/session/aiohttp.py\", line 185, in make_request\n",
            "    response = self.check_response(\n",
            "               ^^^^^^^^^^^^^^^^^^^^\n",
            "  File \"/usr/local/lib/python3.11/dist-packages/aiogram/client/session/base.py\", line 120, in check_response\n",
            "    raise TelegramBadRequest(method=method, message=description)\n",
            "aiogram.exceptions.TelegramBadRequest: Telegram server says - Bad Request: can't parse entities: Unsupported start tag \"_io.bufferedreader\" at byte offset 173\n"
          ]
        },
        {
          "output_type": "stream",
          "name": "stdout",
          "text": [
            "Аудиофайл создан.\n"
          ]
        },
        {
          "output_type": "stream",
          "name": "stderr",
          "text": [
            "ERROR:aiogram.event:Cause exception while process update id=995587223 by bot id=7954916275\n",
            "TelegramBadRequest: Telegram server says - Bad Request: can't parse entities: Unsupported start tag \"_io.bufferedreader\" at byte offset 173\n",
            "Traceback (most recent call last):\n",
            "  File \"<ipython-input-6-d12a11f58cce>\", line 106, in echo\n",
            "    await message.answer_audio(audio)\n",
            "          ^^^^^^^^^^^^^^^^^^^^^^^^^^^\n",
            "  File \"/usr/local/lib/python3.11/dist-packages/aiogram/types/message.py\", line 1022, in answer_audio\n",
            "    return SendAudio(\n",
            "           ^^^^^^^^^^\n",
            "  File \"/usr/local/lib/python3.11/dist-packages/pydantic/main.py\", line 214, in __init__\n",
            "    validated_self = self.__pydantic_validator__.validate_python(data, self_instance=self)\n",
            "                     ^^^^^^^^^^^^^^^^^^^^^^^^^^^^^^^^^^^^^^^^^^^^^^^^^^^^^^^^^^^^^^^^^^^^^\n",
            "pydantic_core._pydantic_core.ValidationError: 2 validation errors for SendAudio\n",
            "audio.is-instance[InputFile]\n",
            "  Input should be an instance of InputFile [type=is_instance_of, input_value=<_io.BufferedReader name='response.mp3'>, input_type=BufferedReader]\n",
            "    For further information visit https://errors.pydantic.dev/2.10/v/is_instance_of\n",
            "audio.str\n",
            "  Input should be a valid string [type=string_type, input_value=<_io.BufferedReader name='response.mp3'>, input_type=BufferedReader]\n",
            "    For further information visit https://errors.pydantic.dev/2.10/v/string_type\n",
            "\n",
            "During handling of the above exception, another exception occurred:\n",
            "\n",
            "Traceback (most recent call last):\n",
            "  File \"/usr/local/lib/python3.11/dist-packages/aiogram/dispatcher/dispatcher.py\", line 309, in _process_update\n",
            "    response = await self.feed_update(bot, update, **kwargs)\n",
            "               ^^^^^^^^^^^^^^^^^^^^^^^^^^^^^^^^^^^^^^^^^^^^^\n",
            "  File \"/usr/local/lib/python3.11/dist-packages/aiogram/dispatcher/dispatcher.py\", line 158, in feed_update\n",
            "    response = await self.update.wrap_outer_middleware(\n",
            "               ^^^^^^^^^^^^^^^^^^^^^^^^^^^^^^^^^^^^^^^^\n",
            "  File \"/usr/local/lib/python3.11/dist-packages/aiogram/dispatcher/middlewares/error.py\", line 25, in __call__\n",
            "    return await handler(event, data)\n",
            "           ^^^^^^^^^^^^^^^^^^^^^^^^^^\n",
            "  File \"/usr/local/lib/python3.11/dist-packages/aiogram/dispatcher/middlewares/user_context.py\", line 56, in __call__\n",
            "    return await handler(event, data)\n",
            "           ^^^^^^^^^^^^^^^^^^^^^^^^^^\n",
            "  File \"/usr/local/lib/python3.11/dist-packages/aiogram/fsm/middleware.py\", line 42, in __call__\n",
            "    return await handler(event, data)\n",
            "           ^^^^^^^^^^^^^^^^^^^^^^^^^^\n",
            "  File \"/usr/local/lib/python3.11/dist-packages/aiogram/dispatcher/event/telegram.py\", line 121, in trigger\n",
            "    return await wrapped_inner(event, kwargs)\n",
            "           ^^^^^^^^^^^^^^^^^^^^^^^^^^^^^^^^^^\n",
            "  File \"/usr/local/lib/python3.11/dist-packages/aiogram/dispatcher/event/handler.py\", line 43, in call\n",
            "    return await wrapped()\n",
            "           ^^^^^^^^^^^^^^^\n",
            "  File \"/usr/local/lib/python3.11/dist-packages/aiogram/dispatcher/dispatcher.py\", line 276, in _listen_update\n",
            "    return await self.propagate_event(update_type=update_type, event=event, **kwargs)\n",
            "           ^^^^^^^^^^^^^^^^^^^^^^^^^^^^^^^^^^^^^^^^^^^^^^^^^^^^^^^^^^^^^^^^^^^^^^^^^^\n",
            "  File \"/usr/local/lib/python3.11/dist-packages/aiogram/dispatcher/router.py\", line 146, in propagate_event\n",
            "    return await observer.wrap_outer_middleware(_wrapped, event=event, data=kwargs)\n",
            "           ^^^^^^^^^^^^^^^^^^^^^^^^^^^^^^^^^^^^^^^^^^^^^^^^^^^^^^^^^^^^^^^^^^^^^^^^\n",
            "  File \"/usr/local/lib/python3.11/dist-packages/aiogram/dispatcher/router.py\", line 141, in _wrapped\n",
            "    return await self._propagate_event(\n",
            "           ^^^^^^^^^^^^^^^^^^^^^^^^^^^^\n",
            "  File \"/usr/local/lib/python3.11/dist-packages/aiogram/dispatcher/router.py\", line 166, in _propagate_event\n",
            "    response = await observer.trigger(event, **kwargs)\n",
            "               ^^^^^^^^^^^^^^^^^^^^^^^^^^^^^^^^^^^^^^^\n",
            "  File \"/usr/local/lib/python3.11/dist-packages/aiogram/dispatcher/event/telegram.py\", line 121, in trigger\n",
            "    return await wrapped_inner(event, kwargs)\n",
            "           ^^^^^^^^^^^^^^^^^^^^^^^^^^^^^^^^^^\n",
            "  File \"/usr/local/lib/python3.11/dist-packages/aiogram/dispatcher/event/handler.py\", line 43, in call\n",
            "    return await wrapped()\n",
            "           ^^^^^^^^^^^^^^^\n",
            "  File \"<ipython-input-6-d12a11f58cce>\", line 121, in echo\n",
            "    await message.answer(f\"Произошла ошибка: {str(e)}\")  # Исправлено: str(e) для корректного вывода ошибки\n",
            "    ^^^^^^^^^^^^^^^^^^^^^^^^^^^^^^^^^^^^^^^^^^^^^^^^^^^\n",
            "  File \"/usr/local/lib/python3.11/dist-packages/aiogram/methods/base.py\", line 84, in emit\n",
            "    return await bot(self)\n",
            "           ^^^^^^^^^^^^^^^\n",
            "  File \"/usr/local/lib/python3.11/dist-packages/aiogram/client/bot.py\", line 498, in __call__\n",
            "    return await self.session(self, method, timeout=request_timeout)\n",
            "           ^^^^^^^^^^^^^^^^^^^^^^^^^^^^^^^^^^^^^^^^^^^^^^^^^^^^^^^^^\n",
            "  File \"/usr/local/lib/python3.11/dist-packages/aiogram/client/session/base.py\", line 254, in __call__\n",
            "    return cast(TelegramType, await middleware(bot, method))\n",
            "                              ^^^^^^^^^^^^^^^^^^^^^^^^^^^^^\n",
            "  File \"/usr/local/lib/python3.11/dist-packages/aiogram/client/session/aiohttp.py\", line 185, in make_request\n",
            "    response = self.check_response(\n",
            "               ^^^^^^^^^^^^^^^^^^^^\n",
            "  File \"/usr/local/lib/python3.11/dist-packages/aiogram/client/session/base.py\", line 120, in check_response\n",
            "    raise TelegramBadRequest(method=method, message=description)\n",
            "aiogram.exceptions.TelegramBadRequest: Telegram server says - Bad Request: can't parse entities: Unsupported start tag \"_io.bufferedreader\" at byte offset 173\n"
          ]
        },
        {
          "output_type": "stream",
          "name": "stdout",
          "text": [
            "Аудиофайл создан.\n"
          ]
        },
        {
          "output_type": "stream",
          "name": "stderr",
          "text": [
            "/usr/local/lib/python3.11/dist-packages/transformers/generation/configuration_utils.py:628: UserWarning: `do_sample` is set to `False`. However, `temperature` is set to `0.7` -- this flag is only used in sample-based generation modes. You should set `do_sample=True` or unset `temperature`.\n",
            "  warnings.warn(\n",
            "/usr/local/lib/python3.11/dist-packages/transformers/generation/configuration_utils.py:633: UserWarning: `do_sample` is set to `False`. However, `top_p` is set to `0.95` -- this flag is only used in sample-based generation modes. You should set `do_sample=True` or unset `top_p`.\n",
            "  warnings.warn(\n",
            "ERROR:aiogram.event:Cause exception while process update id=995587224 by bot id=7954916275\n",
            "TelegramBadRequest: Telegram server says - Bad Request: can't parse entities: Unsupported start tag \"_io.bufferedreader\" at byte offset 173\n",
            "Traceback (most recent call last):\n",
            "  File \"<ipython-input-6-d12a11f58cce>\", line 106, in echo\n",
            "    await message.answer_audio(audio)\n",
            "          ^^^^^^^^^^^^^^^^^^^^^^^^^^^\n",
            "  File \"/usr/local/lib/python3.11/dist-packages/aiogram/types/message.py\", line 1022, in answer_audio\n",
            "    return SendAudio(\n",
            "           ^^^^^^^^^^\n",
            "  File \"/usr/local/lib/python3.11/dist-packages/pydantic/main.py\", line 214, in __init__\n",
            "    validated_self = self.__pydantic_validator__.validate_python(data, self_instance=self)\n",
            "                     ^^^^^^^^^^^^^^^^^^^^^^^^^^^^^^^^^^^^^^^^^^^^^^^^^^^^^^^^^^^^^^^^^^^^^\n",
            "pydantic_core._pydantic_core.ValidationError: 2 validation errors for SendAudio\n",
            "audio.is-instance[InputFile]\n",
            "  Input should be an instance of InputFile [type=is_instance_of, input_value=<_io.BufferedReader name='response.mp3'>, input_type=BufferedReader]\n",
            "    For further information visit https://errors.pydantic.dev/2.10/v/is_instance_of\n",
            "audio.str\n",
            "  Input should be a valid string [type=string_type, input_value=<_io.BufferedReader name='response.mp3'>, input_type=BufferedReader]\n",
            "    For further information visit https://errors.pydantic.dev/2.10/v/string_type\n",
            "\n",
            "During handling of the above exception, another exception occurred:\n",
            "\n",
            "Traceback (most recent call last):\n",
            "  File \"/usr/local/lib/python3.11/dist-packages/aiogram/dispatcher/dispatcher.py\", line 309, in _process_update\n",
            "    response = await self.feed_update(bot, update, **kwargs)\n",
            "               ^^^^^^^^^^^^^^^^^^^^^^^^^^^^^^^^^^^^^^^^^^^^^\n",
            "  File \"/usr/local/lib/python3.11/dist-packages/aiogram/dispatcher/dispatcher.py\", line 158, in feed_update\n",
            "    response = await self.update.wrap_outer_middleware(\n",
            "               ^^^^^^^^^^^^^^^^^^^^^^^^^^^^^^^^^^^^^^^^\n",
            "  File \"/usr/local/lib/python3.11/dist-packages/aiogram/dispatcher/middlewares/error.py\", line 25, in __call__\n",
            "    return await handler(event, data)\n",
            "           ^^^^^^^^^^^^^^^^^^^^^^^^^^\n",
            "  File \"/usr/local/lib/python3.11/dist-packages/aiogram/dispatcher/middlewares/user_context.py\", line 56, in __call__\n",
            "    return await handler(event, data)\n",
            "           ^^^^^^^^^^^^^^^^^^^^^^^^^^\n",
            "  File \"/usr/local/lib/python3.11/dist-packages/aiogram/fsm/middleware.py\", line 42, in __call__\n",
            "    return await handler(event, data)\n",
            "           ^^^^^^^^^^^^^^^^^^^^^^^^^^\n",
            "  File \"/usr/local/lib/python3.11/dist-packages/aiogram/dispatcher/event/telegram.py\", line 121, in trigger\n",
            "    return await wrapped_inner(event, kwargs)\n",
            "           ^^^^^^^^^^^^^^^^^^^^^^^^^^^^^^^^^^\n",
            "  File \"/usr/local/lib/python3.11/dist-packages/aiogram/dispatcher/event/handler.py\", line 43, in call\n",
            "    return await wrapped()\n",
            "           ^^^^^^^^^^^^^^^\n",
            "  File \"/usr/local/lib/python3.11/dist-packages/aiogram/dispatcher/dispatcher.py\", line 276, in _listen_update\n",
            "    return await self.propagate_event(update_type=update_type, event=event, **kwargs)\n",
            "           ^^^^^^^^^^^^^^^^^^^^^^^^^^^^^^^^^^^^^^^^^^^^^^^^^^^^^^^^^^^^^^^^^^^^^^^^^^\n",
            "  File \"/usr/local/lib/python3.11/dist-packages/aiogram/dispatcher/router.py\", line 146, in propagate_event\n",
            "    return await observer.wrap_outer_middleware(_wrapped, event=event, data=kwargs)\n",
            "           ^^^^^^^^^^^^^^^^^^^^^^^^^^^^^^^^^^^^^^^^^^^^^^^^^^^^^^^^^^^^^^^^^^^^^^^^\n",
            "  File \"/usr/local/lib/python3.11/dist-packages/aiogram/dispatcher/router.py\", line 141, in _wrapped\n",
            "    return await self._propagate_event(\n",
            "           ^^^^^^^^^^^^^^^^^^^^^^^^^^^^\n",
            "  File \"/usr/local/lib/python3.11/dist-packages/aiogram/dispatcher/router.py\", line 166, in _propagate_event\n",
            "    response = await observer.trigger(event, **kwargs)\n",
            "               ^^^^^^^^^^^^^^^^^^^^^^^^^^^^^^^^^^^^^^^\n",
            "  File \"/usr/local/lib/python3.11/dist-packages/aiogram/dispatcher/event/telegram.py\", line 121, in trigger\n",
            "    return await wrapped_inner(event, kwargs)\n",
            "           ^^^^^^^^^^^^^^^^^^^^^^^^^^^^^^^^^^\n",
            "  File \"/usr/local/lib/python3.11/dist-packages/aiogram/dispatcher/event/handler.py\", line 43, in call\n",
            "    return await wrapped()\n",
            "           ^^^^^^^^^^^^^^^\n",
            "  File \"<ipython-input-6-d12a11f58cce>\", line 121, in echo\n",
            "    await message.answer(f\"Произошла ошибка: {str(e)}\")  # Исправлено: str(e) для корректного вывода ошибки\n",
            "    ^^^^^^^^^^^^^^^^^^^^^^^^^^^^^^^^^^^^^^^^^^^^^^^^^^^\n",
            "  File \"/usr/local/lib/python3.11/dist-packages/aiogram/methods/base.py\", line 84, in emit\n",
            "    return await bot(self)\n",
            "           ^^^^^^^^^^^^^^^\n",
            "  File \"/usr/local/lib/python3.11/dist-packages/aiogram/client/bot.py\", line 498, in __call__\n",
            "    return await self.session(self, method, timeout=request_timeout)\n",
            "           ^^^^^^^^^^^^^^^^^^^^^^^^^^^^^^^^^^^^^^^^^^^^^^^^^^^^^^^^^\n",
            "  File \"/usr/local/lib/python3.11/dist-packages/aiogram/client/session/base.py\", line 254, in __call__\n",
            "    return cast(TelegramType, await middleware(bot, method))\n",
            "                              ^^^^^^^^^^^^^^^^^^^^^^^^^^^^^\n",
            "  File \"/usr/local/lib/python3.11/dist-packages/aiogram/client/session/aiohttp.py\", line 185, in make_request\n",
            "    response = self.check_response(\n",
            "               ^^^^^^^^^^^^^^^^^^^^\n",
            "  File \"/usr/local/lib/python3.11/dist-packages/aiogram/client/session/base.py\", line 120, in check_response\n",
            "    raise TelegramBadRequest(method=method, message=description)\n",
            "aiogram.exceptions.TelegramBadRequest: Telegram server says - Bad Request: can't parse entities: Unsupported start tag \"_io.bufferedreader\" at byte offset 173\n"
          ]
        },
        {
          "output_type": "stream",
          "name": "stdout",
          "text": [
            "Аудиофайл создан.\n"
          ]
        }
      ]
    },
    {
      "cell_type": "code",
      "source": [],
      "metadata": {
        "id": "AE9OeDAXXw98"
      },
      "execution_count": null,
      "outputs": []
    }
  ]
}