{
  "nbformat": 4,
  "nbformat_minor": 0,
  "metadata": {
    "colab": {
      "provenance": [],
      "gpuType": "T4",
      "authorship_tag": "ABX9TyOaLy4wADMrT8/uL740RqYo",
      "include_colab_link": true
    },
    "kernelspec": {
      "name": "python3",
      "display_name": "Python 3"
    },
    "language_info": {
      "name": "python"
    },
    "accelerator": "GPU"
  },
  "cells": [
    {
      "cell_type": "markdown",
      "metadata": {
        "id": "view-in-github",
        "colab_type": "text"
      },
      "source": [
        "<a href=\"https://colab.research.google.com/github/Vadim-sys-create/TTS/blob/main/%D0%9A%D0%BE%D0%BF%D0%B8%D1%8F_%D0%B1%D0%BB%D0%BE%D0%BA%D0%BD%D0%BE%D1%82%D0%B0_%22%D0%9A%D0%BE%D0%BF%D0%B8%D1%8F_%D0%B1%D0%BB%D0%BE%D0%BA%D0%BD%D0%BE%D1%82%D0%B0_%22Untitled19_ipynb%22%22.ipynb\" target=\"_parent\"><img src=\"https://colab.research.google.com/assets/colab-badge.svg\" alt=\"Open In Colab\"/></a>"
      ]
    },
    {
      "cell_type": "code",
      "source": [
        "!pip install gtts"
      ],
      "metadata": {
        "colab": {
          "base_uri": "https://localhost:8080/"
        },
        "id": "mpzv7lhON81i",
        "outputId": "6cea5d0b-9403-4f1f-9d78-03b127fc61c9"
      },
      "execution_count": 4,
      "outputs": [
        {
          "output_type": "stream",
          "name": "stdout",
          "text": [
            "Collecting gtts\n",
            "  Downloading gTTS-2.5.4-py3-none-any.whl.metadata (4.1 kB)\n",
            "Requirement already satisfied: requests<3,>=2.27 in /usr/local/lib/python3.11/dist-packages (from gtts) (2.32.3)\n",
            "Requirement already satisfied: click<8.2,>=7.1 in /usr/local/lib/python3.11/dist-packages (from gtts) (8.1.8)\n",
            "Requirement already satisfied: charset-normalizer<4,>=2 in /usr/local/lib/python3.11/dist-packages (from requests<3,>=2.27->gtts) (3.4.1)\n",
            "Requirement already satisfied: idna<4,>=2.5 in /usr/local/lib/python3.11/dist-packages (from requests<3,>=2.27->gtts) (3.10)\n",
            "Requirement already satisfied: urllib3<3,>=1.21.1 in /usr/local/lib/python3.11/dist-packages (from requests<3,>=2.27->gtts) (2.3.0)\n",
            "Requirement already satisfied: certifi>=2017.4.17 in /usr/local/lib/python3.11/dist-packages (from requests<3,>=2.27->gtts) (2025.1.31)\n",
            "Downloading gTTS-2.5.4-py3-none-any.whl (29 kB)\n",
            "Installing collected packages: gtts\n",
            "Successfully installed gtts-2.5.4\n"
          ]
        }
      ]
    },
    {
      "cell_type": "code",
      "source": [
        "!pip install --force-reinstall gtts"
      ],
      "metadata": {
        "colab": {
          "base_uri": "https://localhost:8080/",
          "height": 998
        },
        "id": "iU2LUOEKRPLt",
        "outputId": "9a428791-0de1-4939-fa92-37d88061ab2e"
      },
      "execution_count": null,
      "outputs": [
        {
          "output_type": "stream",
          "name": "stdout",
          "text": [
            "Collecting gtts\n",
            "  Using cached gTTS-2.5.4-py3-none-any.whl.metadata (4.1 kB)\n",
            "Collecting requests<3,>=2.27 (from gtts)\n",
            "  Using cached requests-2.32.3-py3-none-any.whl.metadata (4.6 kB)\n",
            "Collecting click<8.2,>=7.1 (from gtts)\n",
            "  Using cached click-8.1.8-py3-none-any.whl.metadata (2.3 kB)\n",
            "Collecting charset-normalizer<4,>=2 (from requests<3,>=2.27->gtts)\n",
            "  Using cached charset_normalizer-3.4.1-cp311-cp311-manylinux_2_17_x86_64.manylinux2014_x86_64.whl.metadata (35 kB)\n",
            "Collecting idna<4,>=2.5 (from requests<3,>=2.27->gtts)\n",
            "  Using cached idna-3.10-py3-none-any.whl.metadata (10 kB)\n",
            "Collecting urllib3<3,>=1.21.1 (from requests<3,>=2.27->gtts)\n",
            "  Using cached urllib3-2.3.0-py3-none-any.whl.metadata (6.5 kB)\n",
            "Collecting certifi>=2017.4.17 (from requests<3,>=2.27->gtts)\n",
            "  Using cached certifi-2025.1.31-py3-none-any.whl.metadata (2.5 kB)\n",
            "Using cached gTTS-2.5.4-py3-none-any.whl (29 kB)\n",
            "Using cached click-8.1.8-py3-none-any.whl (98 kB)\n",
            "Using cached requests-2.32.3-py3-none-any.whl (64 kB)\n",
            "Using cached certifi-2025.1.31-py3-none-any.whl (166 kB)\n",
            "Using cached charset_normalizer-3.4.1-cp311-cp311-manylinux_2_17_x86_64.manylinux2014_x86_64.whl (143 kB)\n",
            "Using cached idna-3.10-py3-none-any.whl (70 kB)\n",
            "Using cached urllib3-2.3.0-py3-none-any.whl (128 kB)\n",
            "Installing collected packages: urllib3, idna, click, charset-normalizer, certifi, requests, gtts\n",
            "  Attempting uninstall: urllib3\n",
            "    Found existing installation: urllib3 2.3.0\n",
            "    Uninstalling urllib3-2.3.0:\n",
            "      Successfully uninstalled urllib3-2.3.0\n",
            "  Attempting uninstall: idna\n",
            "    Found existing installation: idna 3.10\n",
            "    Uninstalling idna-3.10:\n",
            "      Successfully uninstalled idna-3.10\n",
            "  Attempting uninstall: click\n",
            "    Found existing installation: click 8.1.8\n",
            "    Uninstalling click-8.1.8:\n",
            "      Successfully uninstalled click-8.1.8\n",
            "  Attempting uninstall: charset-normalizer\n",
            "    Found existing installation: charset-normalizer 3.4.1\n",
            "    Uninstalling charset-normalizer-3.4.1:\n",
            "      Successfully uninstalled charset-normalizer-3.4.1\n",
            "  Attempting uninstall: certifi\n",
            "    Found existing installation: certifi 2025.1.31\n",
            "    Uninstalling certifi-2025.1.31:\n",
            "      Successfully uninstalled certifi-2025.1.31\n",
            "  Attempting uninstall: requests\n",
            "    Found existing installation: requests 2.32.3\n",
            "    Uninstalling requests-2.32.3:\n",
            "      Successfully uninstalled requests-2.32.3\n",
            "  Attempting uninstall: gtts\n",
            "    Found existing installation: gTTS 2.5.4\n",
            "    Uninstalling gTTS-2.5.4:\n",
            "      Successfully uninstalled gTTS-2.5.4\n",
            "Successfully installed certifi-2025.1.31 charset-normalizer-3.4.1 click-8.1.8 gtts-2.5.4 idna-3.10 requests-2.32.3 urllib3-2.3.0\n"
          ]
        },
        {
          "output_type": "display_data",
          "data": {
            "application/vnd.colab-display-data+json": {
              "pip_warning": {
                "packages": [
                  "certifi"
                ]
              },
              "id": "4cdd3bc35c084ebba3994b35e08e091f"
            }
          },
          "metadata": {}
        }
      ]
    },
    {
      "cell_type": "code",
      "source": [
        "!pip install flask"
      ],
      "metadata": {
        "colab": {
          "base_uri": "https://localhost:8080/"
        },
        "id": "vuBmwONrYik6",
        "outputId": "52e99e91-9559-40db-cb45-a8d145977af8"
      },
      "execution_count": 1,
      "outputs": [
        {
          "output_type": "stream",
          "name": "stdout",
          "text": [
            "Requirement already satisfied: flask in /usr/local/lib/python3.11/dist-packages (3.1.0)\n",
            "Requirement already satisfied: Werkzeug>=3.1 in /usr/local/lib/python3.11/dist-packages (from flask) (3.1.3)\n",
            "Requirement already satisfied: Jinja2>=3.1.2 in /usr/local/lib/python3.11/dist-packages (from flask) (3.1.5)\n",
            "Requirement already satisfied: itsdangerous>=2.2 in /usr/local/lib/python3.11/dist-packages (from flask) (2.2.0)\n",
            "Requirement already satisfied: click>=8.1.3 in /usr/local/lib/python3.11/dist-packages (from flask) (8.1.8)\n",
            "Requirement already satisfied: blinker>=1.9 in /usr/local/lib/python3.11/dist-packages (from flask) (1.9.0)\n",
            "Requirement already satisfied: MarkupSafe>=2.0 in /usr/local/lib/python3.11/dist-packages (from Jinja2>=3.1.2->flask) (3.0.2)\n"
          ]
        }
      ]
    },
    {
      "cell_type": "code",
      "source": [
        "!python app.py"
      ],
      "metadata": {
        "colab": {
          "base_uri": "https://localhost:8080/"
        },
        "id": "CgWWZS5zaf1f",
        "outputId": "e4c9e5a2-01bb-4fc5-bef8-379f130c0c7c"
      },
      "execution_count": 5,
      "outputs": [
        {
          "output_type": "stream",
          "name": "stdout",
          "text": [
            "2025-03-02 10:33:38.475346: E external/local_xla/xla/stream_executor/cuda/cuda_fft.cc:477] Unable to register cuFFT factory: Attempting to register factory for plugin cuFFT when one has already been registered\n",
            "WARNING: All log messages before absl::InitializeLog() is called are written to STDERR\n",
            "E0000 00:00:1740911618.624095    2442 cuda_dnn.cc:8310] Unable to register cuDNN factory: Attempting to register factory for plugin cuDNN when one has already been registered\n",
            "E0000 00:00:1740911618.647402    2442 cuda_blas.cc:1418] Unable to register cuBLAS factory: Attempting to register factory for plugin cuBLAS when one has already been registered\n",
            "2025-03-02 10:33:38.722348: I tensorflow/core/platform/cpu_feature_guard.cc:210] This TensorFlow binary is optimized to use available CPU instructions in performance-critical operations.\n",
            "To enable the following instructions: AVX2 FMA, in other operations, rebuild TensorFlow with the appropriate compiler flags.\n",
            "Traceback (most recent call last):\n",
            "  File \"/content/app.py\", line 4, in <module>\n",
            "    from fuzzywuzzy import process\n",
            "ModuleNotFoundError: No module named 'fuzzywuzzy'\n"
          ]
        }
      ]
    },
    {
      "cell_type": "code",
      "source": [
        "!pip install aiogram transformers gtts fuzzywuzzy langdetect nest_asyncio"
      ],
      "metadata": {
        "colab": {
          "base_uri": "https://localhost:8080/"
        },
        "id": "JH3ag1hXbdat",
        "outputId": "cab94b10-223b-404c-dbfb-fdbb37d07c62"
      },
      "execution_count": 6,
      "outputs": [
        {
          "output_type": "stream",
          "name": "stdout",
          "text": [
            "Collecting aiogram\n",
            "  Downloading aiogram-3.18.0-py3-none-any.whl.metadata (7.6 kB)\n",
            "Requirement already satisfied: transformers in /usr/local/lib/python3.11/dist-packages (4.48.3)\n",
            "Requirement already satisfied: gtts in /usr/local/lib/python3.11/dist-packages (2.5.4)\n",
            "Collecting fuzzywuzzy\n",
            "  Downloading fuzzywuzzy-0.18.0-py2.py3-none-any.whl.metadata (4.9 kB)\n",
            "Collecting langdetect\n",
            "  Downloading langdetect-1.0.9.tar.gz (981 kB)\n",
            "\u001b[2K     \u001b[90m━━━━━━━━━━━━━━━━━━━━━━━━━━━━━━━━━━━━━━━━\u001b[0m \u001b[32m981.5/981.5 kB\u001b[0m \u001b[31m13.7 MB/s\u001b[0m eta \u001b[36m0:00:00\u001b[0m\n",
            "\u001b[?25h  Preparing metadata (setup.py) ... \u001b[?25l\u001b[?25hdone\n",
            "Requirement already satisfied: nest_asyncio in /usr/local/lib/python3.11/dist-packages (1.6.0)\n",
            "Collecting aiofiles<24.2,>=23.2.1 (from aiogram)\n",
            "  Downloading aiofiles-24.1.0-py3-none-any.whl.metadata (10 kB)\n",
            "Requirement already satisfied: aiohttp<3.12,>=3.9.0 in /usr/local/lib/python3.11/dist-packages (from aiogram) (3.11.13)\n",
            "Requirement already satisfied: certifi>=2023.7.22 in /usr/local/lib/python3.11/dist-packages (from aiogram) (2025.1.31)\n",
            "Collecting magic-filter<1.1,>=1.0.12 (from aiogram)\n",
            "  Downloading magic_filter-1.0.12-py3-none-any.whl.metadata (1.5 kB)\n",
            "Requirement already satisfied: pydantic<2.11,>=2.4.1 in /usr/local/lib/python3.11/dist-packages (from aiogram) (2.10.6)\n",
            "Requirement already satisfied: typing-extensions<=5.0,>=4.7.0 in /usr/local/lib/python3.11/dist-packages (from aiogram) (4.12.2)\n",
            "Requirement already satisfied: filelock in /usr/local/lib/python3.11/dist-packages (from transformers) (3.17.0)\n",
            "Requirement already satisfied: huggingface-hub<1.0,>=0.24.0 in /usr/local/lib/python3.11/dist-packages (from transformers) (0.28.1)\n",
            "Requirement already satisfied: numpy>=1.17 in /usr/local/lib/python3.11/dist-packages (from transformers) (1.26.4)\n",
            "Requirement already satisfied: packaging>=20.0 in /usr/local/lib/python3.11/dist-packages (from transformers) (24.2)\n",
            "Requirement already satisfied: pyyaml>=5.1 in /usr/local/lib/python3.11/dist-packages (from transformers) (6.0.2)\n",
            "Requirement already satisfied: regex!=2019.12.17 in /usr/local/lib/python3.11/dist-packages (from transformers) (2024.11.6)\n",
            "Requirement already satisfied: requests in /usr/local/lib/python3.11/dist-packages (from transformers) (2.32.3)\n",
            "Requirement already satisfied: tokenizers<0.22,>=0.21 in /usr/local/lib/python3.11/dist-packages (from transformers) (0.21.0)\n",
            "Requirement already satisfied: safetensors>=0.4.1 in /usr/local/lib/python3.11/dist-packages (from transformers) (0.5.3)\n",
            "Requirement already satisfied: tqdm>=4.27 in /usr/local/lib/python3.11/dist-packages (from transformers) (4.67.1)\n",
            "Requirement already satisfied: click<8.2,>=7.1 in /usr/local/lib/python3.11/dist-packages (from gtts) (8.1.8)\n",
            "Requirement already satisfied: six in /usr/local/lib/python3.11/dist-packages (from langdetect) (1.17.0)\n",
            "Requirement already satisfied: aiohappyeyeballs>=2.3.0 in /usr/local/lib/python3.11/dist-packages (from aiohttp<3.12,>=3.9.0->aiogram) (2.4.6)\n",
            "Requirement already satisfied: aiosignal>=1.1.2 in /usr/local/lib/python3.11/dist-packages (from aiohttp<3.12,>=3.9.0->aiogram) (1.3.2)\n",
            "Requirement already satisfied: attrs>=17.3.0 in /usr/local/lib/python3.11/dist-packages (from aiohttp<3.12,>=3.9.0->aiogram) (25.1.0)\n",
            "Requirement already satisfied: frozenlist>=1.1.1 in /usr/local/lib/python3.11/dist-packages (from aiohttp<3.12,>=3.9.0->aiogram) (1.5.0)\n",
            "Requirement already satisfied: multidict<7.0,>=4.5 in /usr/local/lib/python3.11/dist-packages (from aiohttp<3.12,>=3.9.0->aiogram) (6.1.0)\n",
            "Requirement already satisfied: propcache>=0.2.0 in /usr/local/lib/python3.11/dist-packages (from aiohttp<3.12,>=3.9.0->aiogram) (0.3.0)\n",
            "Requirement already satisfied: yarl<2.0,>=1.17.0 in /usr/local/lib/python3.11/dist-packages (from aiohttp<3.12,>=3.9.0->aiogram) (1.18.3)\n",
            "Requirement already satisfied: fsspec>=2023.5.0 in /usr/local/lib/python3.11/dist-packages (from huggingface-hub<1.0,>=0.24.0->transformers) (2024.10.0)\n",
            "Requirement already satisfied: annotated-types>=0.6.0 in /usr/local/lib/python3.11/dist-packages (from pydantic<2.11,>=2.4.1->aiogram) (0.7.0)\n",
            "Requirement already satisfied: pydantic-core==2.27.2 in /usr/local/lib/python3.11/dist-packages (from pydantic<2.11,>=2.4.1->aiogram) (2.27.2)\n",
            "Requirement already satisfied: charset-normalizer<4,>=2 in /usr/local/lib/python3.11/dist-packages (from requests->transformers) (3.4.1)\n",
            "Requirement already satisfied: idna<4,>=2.5 in /usr/local/lib/python3.11/dist-packages (from requests->transformers) (3.10)\n",
            "Requirement already satisfied: urllib3<3,>=1.21.1 in /usr/local/lib/python3.11/dist-packages (from requests->transformers) (2.3.0)\n",
            "Downloading aiogram-3.18.0-py3-none-any.whl (612 kB)\n",
            "\u001b[2K   \u001b[90m━━━━━━━━━━━━━━━━━━━━━━━━━━━━━━━━━━━━━━━━\u001b[0m \u001b[32m612.8/612.8 kB\u001b[0m \u001b[31m30.1 MB/s\u001b[0m eta \u001b[36m0:00:00\u001b[0m\n",
            "\u001b[?25hDownloading fuzzywuzzy-0.18.0-py2.py3-none-any.whl (18 kB)\n",
            "Downloading aiofiles-24.1.0-py3-none-any.whl (15 kB)\n",
            "Downloading magic_filter-1.0.12-py3-none-any.whl (11 kB)\n",
            "Building wheels for collected packages: langdetect\n",
            "  Building wheel for langdetect (setup.py) ... \u001b[?25l\u001b[?25hdone\n",
            "  Created wheel for langdetect: filename=langdetect-1.0.9-py3-none-any.whl size=993222 sha256=f146ba80352102d4c8a413edc047c549ba7549f63802962414bed110e02e8612\n",
            "  Stored in directory: /root/.cache/pip/wheels/0a/f2/b2/e5ca405801e05eb7c8ed5b3b4bcf1fcabcd6272c167640072e\n",
            "Successfully built langdetect\n",
            "Installing collected packages: fuzzywuzzy, magic-filter, langdetect, aiofiles, aiogram\n",
            "Successfully installed aiofiles-24.1.0 aiogram-3.18.0 fuzzywuzzy-0.18.0 langdetect-1.0.9 magic-filter-1.0.12\n"
          ]
        }
      ]
    },
    {
      "cell_type": "code",
      "source": [
        "text = \"Привет, это тестовое аудио.\""
      ],
      "metadata": {
        "id": "GNJZ1ow4PYS3"
      },
      "execution_count": 8,
      "outputs": []
    },
    {
      "cell_type": "code",
      "source": [
        "# Установка библиотек\n",
        "!pip install aiogram transformers gtts fuzzywuzzy langdetect nest_asyncio\n",
        "\n",
        "# Импорт библиотек\n",
        "import os\n",
        "from aiogram import Bot, Dispatcher, types\n",
        "from aiogram.filters import Command\n",
        "from aiogram.enums import ParseMode\n",
        "from aiogram.client.default import DefaultBotProperties\n",
        "from transformers import GPT2LMHeadModel, GPT2Tokenizer\n",
        "from gtts import gTTS\n",
        "from fuzzywuzzy import process\n",
        "from langdetect import detect\n",
        "import nest_asyncio\n",
        "\n",
        "# Применяем nest_asyncio для работы в Colab\n",
        "nest_asyncio.apply()\n",
        "\n",
        "# Загрузка модели и токенизатора\n",
        "model_name = \"sberbank-ai/rugpt3large_based_on_gpt2\"\n",
        "tokenizer = GPT2Tokenizer.from_pretrained(model_name)\n",
        "model = GPT2LMHeadModel.from_pretrained(model_name)\n",
        "\n",
        "# Ваши ответы на вопросы\n",
        "my_responses = {\n",
        "    \"Как тебя зовут?\": \"Меня зовут Аватар, и я здесь, чтобы помочь тебе!\",\n",
        "    \"What is your name?\": \"My name is Avatar, and I'm here to help you!\",\n",
        "    \"¿Cómo te llamas?\": \"Me llamo Avatar, y estoy aquí para ayudarte.\",\n",
        "    \"Comment tu t'appelles?\": \"Je m'appelle Avatar, et je suis là pour vous aider.\",\n",
        "}\n",
        "\n",
        "# Функция для генерации ответа\n",
        "def generate_response(question, max_length=50):\n",
        "    # Поиск наиболее похожего вопроса в словаре\n",
        "    match, score = process.extractOne(question, my_responses.keys())\n",
        "\n",
        "    # Если совпадение достаточно точное (например, score > 80), возвращаем ответ\n",
        "    if score > 80:\n",
        "        return my_responses[match]\n",
        "\n",
        "    # Если совпадение неточное, генерируем ответ с помощью модели\n",
        "    inputs = tokenizer(question, return_tensors=\"pt\")\n",
        "    outputs = model.generate(\n",
        "        inputs[\"input_ids\"],\n",
        "        max_length=max_length,\n",
        "        num_return_sequences=1,\n",
        "        no_repeat_ngram_size=2,\n",
        "        top_k=50,\n",
        "        top_p=0.95,\n",
        "        temperature=0.7,\n",
        "    )\n",
        "    return tokenizer.decode(outputs[0], skip_special_tokens=True)\n",
        "\n",
        "# Функция для определения языка текста\n",
        "def detect_language(text):\n",
        "    try:\n",
        "        return detect(text)\n",
        "    except:\n",
        "        return 'ru'  # По умолчанию используем русский язык\n",
        "\n",
        "# Функция для создания аудио из текста\n",
        "def create_audio_from_text(text, output_file=\"response.mp3\"):\n",
        "    lang = detect_language(text)  # Автоматически определяем язык\n",
        "    tts = gTTS(text, lang=lang)\n",
        "    tts.save(output_file)\n",
        "    return output_file\n",
        "\n",
        "# Инициализация бота\n",
        "API_TOKEN = '7954916275:AAEoTnpSPG_DRajIGC859AqOmVejyrn7VL0'  # Замените на ваш токен\n",
        "bot = Bot(token=API_TOKEN, default=DefaultBotProperties(parse_mode=ParseMode.HTML))\n",
        "dp = Dispatcher()\n",
        "\n",
        "# Гифки и картинки для ответов\n",
        "happy_gif = \"https://media.giphy.com/media/3o7aTskHEUdgCQAXde/giphy.gif\"  # Пример гифки\n",
        "thinking_image = \"https://example.com/thinking.jpg\"  # Пример картинки\n",
        "\n",
        "# Обработчик команды /start\n",
        "@dp.message(Command(\"start\"))\n",
        "async def send_welcome(message: types.Message):\n",
        "    await message.answer(\"Привет! Я Аватар. Задай мне вопрос!\")\n",
        "    await message.answer_animation(happy_gif)  # Отправляем гифку\n",
        "\n",
        "# Обработчик текстовых сообщений\n",
        "@dp.message()\n",
        "async def echo(message: types.Message):\n",
        "    user_input = message.text\n",
        "\n",
        "    if user_input.lower() in [\"выход\", \"exit\", \"quit\"]:\n",
        "        await message.answer(\"Аватар: Пока!\")\n",
        "        return\n",
        "\n",
        "    try:\n",
        "        # Генерация ответа\n",
        "        response = generate_response(user_input)\n",
        "        await message.answer(f\"Аватар: {response}\")\n",
        "\n",
        "        # Создание аудио\n",
        "        audio_file = create_audio_from_text(response)\n",
        "\n",
        "        # Проверка, создан ли аудиофайл\n",
        "        if os.path.exists(audio_file):\n",
        "            print(\"Аудиофайл создан.\")  # Для отладки\n",
        "\n",
        "            # Отправка аудио (используем путь к файлу)\n",
        "            with open(audio_file, \"rb\") as audio:\n",
        "                await message.answer_audio(audio)\n",
        "        else:\n",
        "            print(\"Ошибка: аудиофайл не создан.\")  # Для отладки\n",
        "            await message.answer(\"Не удалось создать аудио.\")\n",
        "\n",
        "        # Отправка гифки или картинки\n",
        "        if \"радост\" in response.lower():\n",
        "            await message.answer_animation(happy_gif)  # Отправляем гифку\n",
        "        else:\n",
        "            await message.answer_photo(thinking_image)  # Отправляем картинку\n",
        "\n",
        "        # Удаление временного файла\n",
        "        if os.path.exists(audio_file):\n",
        "            os.remove(audio_file)\n",
        "    except Exception as e:\n",
        "        await message.answer(f\"Произошла ошибка: {str(e)}\")  # Исправлено: str(e) для корректного вывода ошибки\n",
        "\n",
        "# Запуск бота\n",
        "async def start_bot():\n",
        "    await dp.start_polling(bot)\n",
        "\n",
        "# Запуск бота в Colab\n",
        "await start_bot()"
      ],
      "metadata": {
        "colab": {
          "base_uri": "https://localhost:8080/"
        },
        "id": "Vau73KauV78s",
        "outputId": "56d0bd03-864a-4ec2-efb0-bf2a01abf134"
      },
      "execution_count": 9,
      "outputs": [
        {
          "output_type": "stream",
          "name": "stdout",
          "text": [
            "Requirement already satisfied: aiogram in /usr/local/lib/python3.11/dist-packages (3.18.0)\n",
            "Requirement already satisfied: transformers in /usr/local/lib/python3.11/dist-packages (4.48.3)\n",
            "Requirement already satisfied: gtts in /usr/local/lib/python3.11/dist-packages (2.5.4)\n",
            "Requirement already satisfied: fuzzywuzzy in /usr/local/lib/python3.11/dist-packages (0.18.0)\n",
            "Requirement already satisfied: langdetect in /usr/local/lib/python3.11/dist-packages (1.0.9)\n",
            "Requirement already satisfied: nest_asyncio in /usr/local/lib/python3.11/dist-packages (1.6.0)\n",
            "Requirement already satisfied: aiofiles<24.2,>=23.2.1 in /usr/local/lib/python3.11/dist-packages (from aiogram) (24.1.0)\n",
            "Requirement already satisfied: aiohttp<3.12,>=3.9.0 in /usr/local/lib/python3.11/dist-packages (from aiogram) (3.11.13)\n",
            "Requirement already satisfied: certifi>=2023.7.22 in /usr/local/lib/python3.11/dist-packages (from aiogram) (2025.1.31)\n",
            "Requirement already satisfied: magic-filter<1.1,>=1.0.12 in /usr/local/lib/python3.11/dist-packages (from aiogram) (1.0.12)\n",
            "Requirement already satisfied: pydantic<2.11,>=2.4.1 in /usr/local/lib/python3.11/dist-packages (from aiogram) (2.10.6)\n",
            "Requirement already satisfied: typing-extensions<=5.0,>=4.7.0 in /usr/local/lib/python3.11/dist-packages (from aiogram) (4.12.2)\n",
            "Requirement already satisfied: filelock in /usr/local/lib/python3.11/dist-packages (from transformers) (3.17.0)\n",
            "Requirement already satisfied: huggingface-hub<1.0,>=0.24.0 in /usr/local/lib/python3.11/dist-packages (from transformers) (0.28.1)\n",
            "Requirement already satisfied: numpy>=1.17 in /usr/local/lib/python3.11/dist-packages (from transformers) (1.26.4)\n",
            "Requirement already satisfied: packaging>=20.0 in /usr/local/lib/python3.11/dist-packages (from transformers) (24.2)\n",
            "Requirement already satisfied: pyyaml>=5.1 in /usr/local/lib/python3.11/dist-packages (from transformers) (6.0.2)\n",
            "Requirement already satisfied: regex!=2019.12.17 in /usr/local/lib/python3.11/dist-packages (from transformers) (2024.11.6)\n",
            "Requirement already satisfied: requests in /usr/local/lib/python3.11/dist-packages (from transformers) (2.32.3)\n",
            "Requirement already satisfied: tokenizers<0.22,>=0.21 in /usr/local/lib/python3.11/dist-packages (from transformers) (0.21.0)\n",
            "Requirement already satisfied: safetensors>=0.4.1 in /usr/local/lib/python3.11/dist-packages (from transformers) (0.5.3)\n",
            "Requirement already satisfied: tqdm>=4.27 in /usr/local/lib/python3.11/dist-packages (from transformers) (4.67.1)\n",
            "Requirement already satisfied: click<8.2,>=7.1 in /usr/local/lib/python3.11/dist-packages (from gtts) (8.1.8)\n",
            "Requirement already satisfied: six in /usr/local/lib/python3.11/dist-packages (from langdetect) (1.17.0)\n",
            "Requirement already satisfied: aiohappyeyeballs>=2.3.0 in /usr/local/lib/python3.11/dist-packages (from aiohttp<3.12,>=3.9.0->aiogram) (2.4.6)\n",
            "Requirement already satisfied: aiosignal>=1.1.2 in /usr/local/lib/python3.11/dist-packages (from aiohttp<3.12,>=3.9.0->aiogram) (1.3.2)\n",
            "Requirement already satisfied: attrs>=17.3.0 in /usr/local/lib/python3.11/dist-packages (from aiohttp<3.12,>=3.9.0->aiogram) (25.1.0)\n",
            "Requirement already satisfied: frozenlist>=1.1.1 in /usr/local/lib/python3.11/dist-packages (from aiohttp<3.12,>=3.9.0->aiogram) (1.5.0)\n",
            "Requirement already satisfied: multidict<7.0,>=4.5 in /usr/local/lib/python3.11/dist-packages (from aiohttp<3.12,>=3.9.0->aiogram) (6.1.0)\n",
            "Requirement already satisfied: propcache>=0.2.0 in /usr/local/lib/python3.11/dist-packages (from aiohttp<3.12,>=3.9.0->aiogram) (0.3.0)\n",
            "Requirement already satisfied: yarl<2.0,>=1.17.0 in /usr/local/lib/python3.11/dist-packages (from aiohttp<3.12,>=3.9.0->aiogram) (1.18.3)\n",
            "Requirement already satisfied: fsspec>=2023.5.0 in /usr/local/lib/python3.11/dist-packages (from huggingface-hub<1.0,>=0.24.0->transformers) (2024.10.0)\n",
            "Requirement already satisfied: annotated-types>=0.6.0 in /usr/local/lib/python3.11/dist-packages (from pydantic<2.11,>=2.4.1->aiogram) (0.7.0)\n",
            "Requirement already satisfied: pydantic-core==2.27.2 in /usr/local/lib/python3.11/dist-packages (from pydantic<2.11,>=2.4.1->aiogram) (2.27.2)\n",
            "Requirement already satisfied: charset-normalizer<4,>=2 in /usr/local/lib/python3.11/dist-packages (from requests->transformers) (3.4.1)\n",
            "Requirement already satisfied: idna<4,>=2.5 in /usr/local/lib/python3.11/dist-packages (from requests->transformers) (3.10)\n",
            "Requirement already satisfied: urllib3<3,>=1.21.1 in /usr/local/lib/python3.11/dist-packages (from requests->transformers) (2.3.0)\n"
          ]
        },
        {
          "output_type": "stream",
          "name": "stderr",
          "text": [
            "/usr/local/lib/python3.11/dist-packages/fuzzywuzzy/fuzz.py:11: UserWarning: Using slow pure-python SequenceMatcher. Install python-Levenshtein to remove this warning\n",
            "  warnings.warn('Using slow pure-python SequenceMatcher. Install python-Levenshtein to remove this warning')\n",
            "/usr/local/lib/python3.11/dist-packages/huggingface_hub/utils/_auth.py:104: UserWarning: \n",
            "Error while fetching `HF_TOKEN` secret value from your vault: 'Requesting secret HF_TOKEN timed out. Secrets can only be fetched when running from the Colab UI.'.\n",
            "You are not authenticated with the Hugging Face Hub in this notebook.\n",
            "If the error persists, please let us know by opening an issue on GitHub (https://github.com/huggingface/huggingface_hub/issues/new).\n",
            "  warnings.warn(\n",
            "/usr/local/lib/python3.11/dist-packages/transformers/generation/configuration_utils.py:628: UserWarning: `do_sample` is set to `False`. However, `temperature` is set to `0.7` -- this flag is only used in sample-based generation modes. You should set `do_sample=True` or unset `temperature`.\n",
            "  warnings.warn(\n",
            "/usr/local/lib/python3.11/dist-packages/transformers/generation/configuration_utils.py:633: UserWarning: `do_sample` is set to `False`. However, `top_p` is set to `0.95` -- this flag is only used in sample-based generation modes. You should set `do_sample=True` or unset `top_p`.\n",
            "  warnings.warn(\n",
            "ERROR:aiogram.event:Cause exception while process update id=995587227 by bot id=7954916275\n",
            "TelegramBadRequest: Telegram server says - Bad Request: can't parse entities: Unsupported start tag \"_io.bufferedreader\" at byte offset 173\n",
            "Traceback (most recent call last):\n",
            "  File \"<ipython-input-9-d12a11f58cce>\", line 106, in echo\n",
            "    await message.answer_audio(audio)\n",
            "          ^^^^^^^^^^^^^^^^^^^^^^^^^^^\n",
            "  File \"/usr/local/lib/python3.11/dist-packages/aiogram/types/message.py\", line 1022, in answer_audio\n",
            "    return SendAudio(\n",
            "           ^^^^^^^^^^\n",
            "  File \"/usr/local/lib/python3.11/dist-packages/pydantic/main.py\", line 214, in __init__\n",
            "    validated_self = self.__pydantic_validator__.validate_python(data, self_instance=self)\n",
            "                     ^^^^^^^^^^^^^^^^^^^^^^^^^^^^^^^^^^^^^^^^^^^^^^^^^^^^^^^^^^^^^^^^^^^^^\n",
            "pydantic_core._pydantic_core.ValidationError: 2 validation errors for SendAudio\n",
            "audio.is-instance[InputFile]\n",
            "  Input should be an instance of InputFile [type=is_instance_of, input_value=<_io.BufferedReader name='response.mp3'>, input_type=BufferedReader]\n",
            "    For further information visit https://errors.pydantic.dev/2.10/v/is_instance_of\n",
            "audio.str\n",
            "  Input should be a valid string [type=string_type, input_value=<_io.BufferedReader name='response.mp3'>, input_type=BufferedReader]\n",
            "    For further information visit https://errors.pydantic.dev/2.10/v/string_type\n",
            "\n",
            "During handling of the above exception, another exception occurred:\n",
            "\n",
            "Traceback (most recent call last):\n",
            "  File \"/usr/local/lib/python3.11/dist-packages/aiogram/dispatcher/dispatcher.py\", line 309, in _process_update\n",
            "    response = await self.feed_update(bot, update, **kwargs)\n",
            "               ^^^^^^^^^^^^^^^^^^^^^^^^^^^^^^^^^^^^^^^^^^^^^\n",
            "  File \"/usr/local/lib/python3.11/dist-packages/aiogram/dispatcher/dispatcher.py\", line 158, in feed_update\n",
            "    response = await self.update.wrap_outer_middleware(\n",
            "               ^^^^^^^^^^^^^^^^^^^^^^^^^^^^^^^^^^^^^^^^\n",
            "  File \"/usr/local/lib/python3.11/dist-packages/aiogram/dispatcher/middlewares/error.py\", line 25, in __call__\n",
            "    return await handler(event, data)\n",
            "           ^^^^^^^^^^^^^^^^^^^^^^^^^^\n",
            "  File \"/usr/local/lib/python3.11/dist-packages/aiogram/dispatcher/middlewares/user_context.py\", line 56, in __call__\n",
            "    return await handler(event, data)\n",
            "           ^^^^^^^^^^^^^^^^^^^^^^^^^^\n",
            "  File \"/usr/local/lib/python3.11/dist-packages/aiogram/fsm/middleware.py\", line 42, in __call__\n",
            "    return await handler(event, data)\n",
            "           ^^^^^^^^^^^^^^^^^^^^^^^^^^\n",
            "  File \"/usr/local/lib/python3.11/dist-packages/aiogram/dispatcher/event/telegram.py\", line 121, in trigger\n",
            "    return await wrapped_inner(event, kwargs)\n",
            "           ^^^^^^^^^^^^^^^^^^^^^^^^^^^^^^^^^^\n",
            "  File \"/usr/local/lib/python3.11/dist-packages/aiogram/dispatcher/event/handler.py\", line 43, in call\n",
            "    return await wrapped()\n",
            "           ^^^^^^^^^^^^^^^\n",
            "  File \"/usr/local/lib/python3.11/dist-packages/aiogram/dispatcher/dispatcher.py\", line 276, in _listen_update\n",
            "    return await self.propagate_event(update_type=update_type, event=event, **kwargs)\n",
            "           ^^^^^^^^^^^^^^^^^^^^^^^^^^^^^^^^^^^^^^^^^^^^^^^^^^^^^^^^^^^^^^^^^^^^^^^^^^\n",
            "  File \"/usr/local/lib/python3.11/dist-packages/aiogram/dispatcher/router.py\", line 146, in propagate_event\n",
            "    return await observer.wrap_outer_middleware(_wrapped, event=event, data=kwargs)\n",
            "           ^^^^^^^^^^^^^^^^^^^^^^^^^^^^^^^^^^^^^^^^^^^^^^^^^^^^^^^^^^^^^^^^^^^^^^^^\n",
            "  File \"/usr/local/lib/python3.11/dist-packages/aiogram/dispatcher/router.py\", line 141, in _wrapped\n",
            "    return await self._propagate_event(\n",
            "           ^^^^^^^^^^^^^^^^^^^^^^^^^^^^\n",
            "  File \"/usr/local/lib/python3.11/dist-packages/aiogram/dispatcher/router.py\", line 166, in _propagate_event\n",
            "    response = await observer.trigger(event, **kwargs)\n",
            "               ^^^^^^^^^^^^^^^^^^^^^^^^^^^^^^^^^^^^^^^\n",
            "  File \"/usr/local/lib/python3.11/dist-packages/aiogram/dispatcher/event/telegram.py\", line 121, in trigger\n",
            "    return await wrapped_inner(event, kwargs)\n",
            "           ^^^^^^^^^^^^^^^^^^^^^^^^^^^^^^^^^^\n",
            "  File \"/usr/local/lib/python3.11/dist-packages/aiogram/dispatcher/event/handler.py\", line 43, in call\n",
            "    return await wrapped()\n",
            "           ^^^^^^^^^^^^^^^\n",
            "  File \"<ipython-input-9-d12a11f58cce>\", line 121, in echo\n",
            "    await message.answer(f\"Произошла ошибка: {str(e)}\")  # Исправлено: str(e) для корректного вывода ошибки\n",
            "    ^^^^^^^^^^^^^^^^^^^^^^^^^^^^^^^^^^^^^^^^^^^^^^^^^^^\n",
            "  File \"/usr/local/lib/python3.11/dist-packages/aiogram/methods/base.py\", line 84, in emit\n",
            "    return await bot(self)\n",
            "           ^^^^^^^^^^^^^^^\n",
            "  File \"/usr/local/lib/python3.11/dist-packages/aiogram/client/bot.py\", line 498, in __call__\n",
            "    return await self.session(self, method, timeout=request_timeout)\n",
            "           ^^^^^^^^^^^^^^^^^^^^^^^^^^^^^^^^^^^^^^^^^^^^^^^^^^^^^^^^^\n",
            "  File \"/usr/local/lib/python3.11/dist-packages/aiogram/client/session/base.py\", line 254, in __call__\n",
            "    return cast(TelegramType, await middleware(bot, method))\n",
            "                              ^^^^^^^^^^^^^^^^^^^^^^^^^^^^^\n",
            "  File \"/usr/local/lib/python3.11/dist-packages/aiogram/client/session/aiohttp.py\", line 185, in make_request\n",
            "    response = self.check_response(\n",
            "               ^^^^^^^^^^^^^^^^^^^^\n",
            "  File \"/usr/local/lib/python3.11/dist-packages/aiogram/client/session/base.py\", line 120, in check_response\n",
            "    raise TelegramBadRequest(method=method, message=description)\n",
            "aiogram.exceptions.TelegramBadRequest: Telegram server says - Bad Request: can't parse entities: Unsupported start tag \"_io.bufferedreader\" at byte offset 173\n"
          ]
        },
        {
          "output_type": "stream",
          "name": "stdout",
          "text": [
            "Аудиофайл создан.\n"
          ]
        },
        {
          "output_type": "stream",
          "name": "stderr",
          "text": [
            "/usr/local/lib/python3.11/dist-packages/transformers/generation/configuration_utils.py:628: UserWarning: `do_sample` is set to `False`. However, `temperature` is set to `0.7` -- this flag is only used in sample-based generation modes. You should set `do_sample=True` or unset `temperature`.\n",
            "  warnings.warn(\n",
            "/usr/local/lib/python3.11/dist-packages/transformers/generation/configuration_utils.py:633: UserWarning: `do_sample` is set to `False`. However, `top_p` is set to `0.95` -- this flag is only used in sample-based generation modes. You should set `do_sample=True` or unset `top_p`.\n",
            "  warnings.warn(\n",
            "ERROR:aiogram.event:Cause exception while process update id=995587229 by bot id=7954916275\n",
            "TelegramBadRequest: Telegram server says - Bad Request: can't parse entities: Unsupported start tag \"_io.bufferedreader\" at byte offset 173\n",
            "Traceback (most recent call last):\n",
            "  File \"<ipython-input-9-d12a11f58cce>\", line 106, in echo\n",
            "    await message.answer_audio(audio)\n",
            "          ^^^^^^^^^^^^^^^^^^^^^^^^^^^\n",
            "  File \"/usr/local/lib/python3.11/dist-packages/aiogram/types/message.py\", line 1022, in answer_audio\n",
            "    return SendAudio(\n",
            "           ^^^^^^^^^^\n",
            "  File \"/usr/local/lib/python3.11/dist-packages/pydantic/main.py\", line 214, in __init__\n",
            "    validated_self = self.__pydantic_validator__.validate_python(data, self_instance=self)\n",
            "                     ^^^^^^^^^^^^^^^^^^^^^^^^^^^^^^^^^^^^^^^^^^^^^^^^^^^^^^^^^^^^^^^^^^^^^\n",
            "pydantic_core._pydantic_core.ValidationError: 2 validation errors for SendAudio\n",
            "audio.is-instance[InputFile]\n",
            "  Input should be an instance of InputFile [type=is_instance_of, input_value=<_io.BufferedReader name='response.mp3'>, input_type=BufferedReader]\n",
            "    For further information visit https://errors.pydantic.dev/2.10/v/is_instance_of\n",
            "audio.str\n",
            "  Input should be a valid string [type=string_type, input_value=<_io.BufferedReader name='response.mp3'>, input_type=BufferedReader]\n",
            "    For further information visit https://errors.pydantic.dev/2.10/v/string_type\n",
            "\n",
            "During handling of the above exception, another exception occurred:\n",
            "\n",
            "Traceback (most recent call last):\n",
            "  File \"/usr/local/lib/python3.11/dist-packages/aiogram/dispatcher/dispatcher.py\", line 309, in _process_update\n",
            "    response = await self.feed_update(bot, update, **kwargs)\n",
            "               ^^^^^^^^^^^^^^^^^^^^^^^^^^^^^^^^^^^^^^^^^^^^^\n",
            "  File \"/usr/local/lib/python3.11/dist-packages/aiogram/dispatcher/dispatcher.py\", line 158, in feed_update\n",
            "    response = await self.update.wrap_outer_middleware(\n",
            "               ^^^^^^^^^^^^^^^^^^^^^^^^^^^^^^^^^^^^^^^^\n",
            "  File \"/usr/local/lib/python3.11/dist-packages/aiogram/dispatcher/middlewares/error.py\", line 25, in __call__\n",
            "    return await handler(event, data)\n",
            "           ^^^^^^^^^^^^^^^^^^^^^^^^^^\n",
            "  File \"/usr/local/lib/python3.11/dist-packages/aiogram/dispatcher/middlewares/user_context.py\", line 56, in __call__\n",
            "    return await handler(event, data)\n",
            "           ^^^^^^^^^^^^^^^^^^^^^^^^^^\n",
            "  File \"/usr/local/lib/python3.11/dist-packages/aiogram/fsm/middleware.py\", line 42, in __call__\n",
            "    return await handler(event, data)\n",
            "           ^^^^^^^^^^^^^^^^^^^^^^^^^^\n",
            "  File \"/usr/local/lib/python3.11/dist-packages/aiogram/dispatcher/event/telegram.py\", line 121, in trigger\n",
            "    return await wrapped_inner(event, kwargs)\n",
            "           ^^^^^^^^^^^^^^^^^^^^^^^^^^^^^^^^^^\n",
            "  File \"/usr/local/lib/python3.11/dist-packages/aiogram/dispatcher/event/handler.py\", line 43, in call\n",
            "    return await wrapped()\n",
            "           ^^^^^^^^^^^^^^^\n",
            "  File \"/usr/local/lib/python3.11/dist-packages/aiogram/dispatcher/dispatcher.py\", line 276, in _listen_update\n",
            "    return await self.propagate_event(update_type=update_type, event=event, **kwargs)\n",
            "           ^^^^^^^^^^^^^^^^^^^^^^^^^^^^^^^^^^^^^^^^^^^^^^^^^^^^^^^^^^^^^^^^^^^^^^^^^^\n",
            "  File \"/usr/local/lib/python3.11/dist-packages/aiogram/dispatcher/router.py\", line 146, in propagate_event\n",
            "    return await observer.wrap_outer_middleware(_wrapped, event=event, data=kwargs)\n",
            "           ^^^^^^^^^^^^^^^^^^^^^^^^^^^^^^^^^^^^^^^^^^^^^^^^^^^^^^^^^^^^^^^^^^^^^^^^\n",
            "  File \"/usr/local/lib/python3.11/dist-packages/aiogram/dispatcher/router.py\", line 141, in _wrapped\n",
            "    return await self._propagate_event(\n",
            "           ^^^^^^^^^^^^^^^^^^^^^^^^^^^^\n",
            "  File \"/usr/local/lib/python3.11/dist-packages/aiogram/dispatcher/router.py\", line 166, in _propagate_event\n",
            "    response = await observer.trigger(event, **kwargs)\n",
            "               ^^^^^^^^^^^^^^^^^^^^^^^^^^^^^^^^^^^^^^^\n",
            "  File \"/usr/local/lib/python3.11/dist-packages/aiogram/dispatcher/event/telegram.py\", line 121, in trigger\n",
            "    return await wrapped_inner(event, kwargs)\n",
            "           ^^^^^^^^^^^^^^^^^^^^^^^^^^^^^^^^^^\n",
            "  File \"/usr/local/lib/python3.11/dist-packages/aiogram/dispatcher/event/handler.py\", line 43, in call\n",
            "    return await wrapped()\n",
            "           ^^^^^^^^^^^^^^^\n",
            "  File \"<ipython-input-9-d12a11f58cce>\", line 121, in echo\n",
            "    await message.answer(f\"Произошла ошибка: {str(e)}\")  # Исправлено: str(e) для корректного вывода ошибки\n",
            "    ^^^^^^^^^^^^^^^^^^^^^^^^^^^^^^^^^^^^^^^^^^^^^^^^^^^\n",
            "  File \"/usr/local/lib/python3.11/dist-packages/aiogram/methods/base.py\", line 84, in emit\n",
            "    return await bot(self)\n",
            "           ^^^^^^^^^^^^^^^\n",
            "  File \"/usr/local/lib/python3.11/dist-packages/aiogram/client/bot.py\", line 498, in __call__\n",
            "    return await self.session(self, method, timeout=request_timeout)\n",
            "           ^^^^^^^^^^^^^^^^^^^^^^^^^^^^^^^^^^^^^^^^^^^^^^^^^^^^^^^^^\n",
            "  File \"/usr/local/lib/python3.11/dist-packages/aiogram/client/session/base.py\", line 254, in __call__\n",
            "    return cast(TelegramType, await middleware(bot, method))\n",
            "                              ^^^^^^^^^^^^^^^^^^^^^^^^^^^^^\n",
            "  File \"/usr/local/lib/python3.11/dist-packages/aiogram/client/session/aiohttp.py\", line 185, in make_request\n",
            "    response = self.check_response(\n",
            "               ^^^^^^^^^^^^^^^^^^^^\n",
            "  File \"/usr/local/lib/python3.11/dist-packages/aiogram/client/session/base.py\", line 120, in check_response\n",
            "    raise TelegramBadRequest(method=method, message=description)\n",
            "aiogram.exceptions.TelegramBadRequest: Telegram server says - Bad Request: can't parse entities: Unsupported start tag \"_io.bufferedreader\" at byte offset 173\n"
          ]
        },
        {
          "output_type": "stream",
          "name": "stdout",
          "text": [
            "Аудиофайл создан.\n"
          ]
        },
        {
          "output_type": "stream",
          "name": "stderr",
          "text": [
            "/usr/local/lib/python3.11/dist-packages/transformers/generation/configuration_utils.py:628: UserWarning: `do_sample` is set to `False`. However, `temperature` is set to `0.7` -- this flag is only used in sample-based generation modes. You should set `do_sample=True` or unset `temperature`.\n",
            "  warnings.warn(\n",
            "/usr/local/lib/python3.11/dist-packages/transformers/generation/configuration_utils.py:633: UserWarning: `do_sample` is set to `False`. However, `top_p` is set to `0.95` -- this flag is only used in sample-based generation modes. You should set `do_sample=True` or unset `top_p`.\n",
            "  warnings.warn(\n",
            "ERROR:aiogram.event:Cause exception while process update id=995587230 by bot id=7954916275\n",
            "TelegramBadRequest: Telegram server says - Bad Request: can't parse entities: Unsupported start tag \"_io.bufferedreader\" at byte offset 173\n",
            "Traceback (most recent call last):\n",
            "  File \"<ipython-input-9-d12a11f58cce>\", line 106, in echo\n",
            "    await message.answer_audio(audio)\n",
            "          ^^^^^^^^^^^^^^^^^^^^^^^^^^^\n",
            "  File \"/usr/local/lib/python3.11/dist-packages/aiogram/types/message.py\", line 1022, in answer_audio\n",
            "    return SendAudio(\n",
            "           ^^^^^^^^^^\n",
            "  File \"/usr/local/lib/python3.11/dist-packages/pydantic/main.py\", line 214, in __init__\n",
            "    validated_self = self.__pydantic_validator__.validate_python(data, self_instance=self)\n",
            "                     ^^^^^^^^^^^^^^^^^^^^^^^^^^^^^^^^^^^^^^^^^^^^^^^^^^^^^^^^^^^^^^^^^^^^^\n",
            "pydantic_core._pydantic_core.ValidationError: 2 validation errors for SendAudio\n",
            "audio.is-instance[InputFile]\n",
            "  Input should be an instance of InputFile [type=is_instance_of, input_value=<_io.BufferedReader name='response.mp3'>, input_type=BufferedReader]\n",
            "    For further information visit https://errors.pydantic.dev/2.10/v/is_instance_of\n",
            "audio.str\n",
            "  Input should be a valid string [type=string_type, input_value=<_io.BufferedReader name='response.mp3'>, input_type=BufferedReader]\n",
            "    For further information visit https://errors.pydantic.dev/2.10/v/string_type\n",
            "\n",
            "During handling of the above exception, another exception occurred:\n",
            "\n",
            "Traceback (most recent call last):\n",
            "  File \"/usr/local/lib/python3.11/dist-packages/aiogram/dispatcher/dispatcher.py\", line 309, in _process_update\n",
            "    response = await self.feed_update(bot, update, **kwargs)\n",
            "               ^^^^^^^^^^^^^^^^^^^^^^^^^^^^^^^^^^^^^^^^^^^^^\n",
            "  File \"/usr/local/lib/python3.11/dist-packages/aiogram/dispatcher/dispatcher.py\", line 158, in feed_update\n",
            "    response = await self.update.wrap_outer_middleware(\n",
            "               ^^^^^^^^^^^^^^^^^^^^^^^^^^^^^^^^^^^^^^^^\n",
            "  File \"/usr/local/lib/python3.11/dist-packages/aiogram/dispatcher/middlewares/error.py\", line 25, in __call__\n",
            "    return await handler(event, data)\n",
            "           ^^^^^^^^^^^^^^^^^^^^^^^^^^\n",
            "  File \"/usr/local/lib/python3.11/dist-packages/aiogram/dispatcher/middlewares/user_context.py\", line 56, in __call__\n",
            "    return await handler(event, data)\n",
            "           ^^^^^^^^^^^^^^^^^^^^^^^^^^\n",
            "  File \"/usr/local/lib/python3.11/dist-packages/aiogram/fsm/middleware.py\", line 42, in __call__\n",
            "    return await handler(event, data)\n",
            "           ^^^^^^^^^^^^^^^^^^^^^^^^^^\n",
            "  File \"/usr/local/lib/python3.11/dist-packages/aiogram/dispatcher/event/telegram.py\", line 121, in trigger\n",
            "    return await wrapped_inner(event, kwargs)\n",
            "           ^^^^^^^^^^^^^^^^^^^^^^^^^^^^^^^^^^\n",
            "  File \"/usr/local/lib/python3.11/dist-packages/aiogram/dispatcher/event/handler.py\", line 43, in call\n",
            "    return await wrapped()\n",
            "           ^^^^^^^^^^^^^^^\n",
            "  File \"/usr/local/lib/python3.11/dist-packages/aiogram/dispatcher/dispatcher.py\", line 276, in _listen_update\n",
            "    return await self.propagate_event(update_type=update_type, event=event, **kwargs)\n",
            "           ^^^^^^^^^^^^^^^^^^^^^^^^^^^^^^^^^^^^^^^^^^^^^^^^^^^^^^^^^^^^^^^^^^^^^^^^^^\n",
            "  File \"/usr/local/lib/python3.11/dist-packages/aiogram/dispatcher/router.py\", line 146, in propagate_event\n",
            "    return await observer.wrap_outer_middleware(_wrapped, event=event, data=kwargs)\n",
            "           ^^^^^^^^^^^^^^^^^^^^^^^^^^^^^^^^^^^^^^^^^^^^^^^^^^^^^^^^^^^^^^^^^^^^^^^^\n",
            "  File \"/usr/local/lib/python3.11/dist-packages/aiogram/dispatcher/router.py\", line 141, in _wrapped\n",
            "    return await self._propagate_event(\n",
            "           ^^^^^^^^^^^^^^^^^^^^^^^^^^^^\n",
            "  File \"/usr/local/lib/python3.11/dist-packages/aiogram/dispatcher/router.py\", line 166, in _propagate_event\n",
            "    response = await observer.trigger(event, **kwargs)\n",
            "               ^^^^^^^^^^^^^^^^^^^^^^^^^^^^^^^^^^^^^^^\n",
            "  File \"/usr/local/lib/python3.11/dist-packages/aiogram/dispatcher/event/telegram.py\", line 121, in trigger\n",
            "    return await wrapped_inner(event, kwargs)\n",
            "           ^^^^^^^^^^^^^^^^^^^^^^^^^^^^^^^^^^\n",
            "  File \"/usr/local/lib/python3.11/dist-packages/aiogram/dispatcher/event/handler.py\", line 43, in call\n",
            "    return await wrapped()\n",
            "           ^^^^^^^^^^^^^^^\n",
            "  File \"<ipython-input-9-d12a11f58cce>\", line 121, in echo\n",
            "    await message.answer(f\"Произошла ошибка: {str(e)}\")  # Исправлено: str(e) для корректного вывода ошибки\n",
            "    ^^^^^^^^^^^^^^^^^^^^^^^^^^^^^^^^^^^^^^^^^^^^^^^^^^^\n",
            "  File \"/usr/local/lib/python3.11/dist-packages/aiogram/methods/base.py\", line 84, in emit\n",
            "    return await bot(self)\n",
            "           ^^^^^^^^^^^^^^^\n",
            "  File \"/usr/local/lib/python3.11/dist-packages/aiogram/client/bot.py\", line 498, in __call__\n",
            "    return await self.session(self, method, timeout=request_timeout)\n",
            "           ^^^^^^^^^^^^^^^^^^^^^^^^^^^^^^^^^^^^^^^^^^^^^^^^^^^^^^^^^\n",
            "  File \"/usr/local/lib/python3.11/dist-packages/aiogram/client/session/base.py\", line 254, in __call__\n",
            "    return cast(TelegramType, await middleware(bot, method))\n",
            "                              ^^^^^^^^^^^^^^^^^^^^^^^^^^^^^\n",
            "  File \"/usr/local/lib/python3.11/dist-packages/aiogram/client/session/aiohttp.py\", line 185, in make_request\n",
            "    response = self.check_response(\n",
            "               ^^^^^^^^^^^^^^^^^^^^\n",
            "  File \"/usr/local/lib/python3.11/dist-packages/aiogram/client/session/base.py\", line 120, in check_response\n",
            "    raise TelegramBadRequest(method=method, message=description)\n",
            "aiogram.exceptions.TelegramBadRequest: Telegram server says - Bad Request: can't parse entities: Unsupported start tag \"_io.bufferedreader\" at byte offset 173\n"
          ]
        },
        {
          "output_type": "stream",
          "name": "stdout",
          "text": [
            "Аудиофайл создан.\n"
          ]
        },
        {
          "output_type": "stream",
          "name": "stderr",
          "text": [
            "ERROR:aiogram.event:Cause exception while process update id=995587231 by bot id=7954916275\n",
            "TelegramBadRequest: Telegram server says - Bad Request: can't parse entities: Unsupported start tag \"_io.bufferedreader\" at byte offset 173\n",
            "Traceback (most recent call last):\n",
            "  File \"<ipython-input-9-d12a11f58cce>\", line 106, in echo\n",
            "    await message.answer_audio(audio)\n",
            "          ^^^^^^^^^^^^^^^^^^^^^^^^^^^\n",
            "  File \"/usr/local/lib/python3.11/dist-packages/aiogram/types/message.py\", line 1022, in answer_audio\n",
            "    return SendAudio(\n",
            "           ^^^^^^^^^^\n",
            "  File \"/usr/local/lib/python3.11/dist-packages/pydantic/main.py\", line 214, in __init__\n",
            "    validated_self = self.__pydantic_validator__.validate_python(data, self_instance=self)\n",
            "                     ^^^^^^^^^^^^^^^^^^^^^^^^^^^^^^^^^^^^^^^^^^^^^^^^^^^^^^^^^^^^^^^^^^^^^\n",
            "pydantic_core._pydantic_core.ValidationError: 2 validation errors for SendAudio\n",
            "audio.is-instance[InputFile]\n",
            "  Input should be an instance of InputFile [type=is_instance_of, input_value=<_io.BufferedReader name='response.mp3'>, input_type=BufferedReader]\n",
            "    For further information visit https://errors.pydantic.dev/2.10/v/is_instance_of\n",
            "audio.str\n",
            "  Input should be a valid string [type=string_type, input_value=<_io.BufferedReader name='response.mp3'>, input_type=BufferedReader]\n",
            "    For further information visit https://errors.pydantic.dev/2.10/v/string_type\n",
            "\n",
            "During handling of the above exception, another exception occurred:\n",
            "\n",
            "Traceback (most recent call last):\n",
            "  File \"/usr/local/lib/python3.11/dist-packages/aiogram/dispatcher/dispatcher.py\", line 309, in _process_update\n",
            "    response = await self.feed_update(bot, update, **kwargs)\n",
            "               ^^^^^^^^^^^^^^^^^^^^^^^^^^^^^^^^^^^^^^^^^^^^^\n",
            "  File \"/usr/local/lib/python3.11/dist-packages/aiogram/dispatcher/dispatcher.py\", line 158, in feed_update\n",
            "    response = await self.update.wrap_outer_middleware(\n",
            "               ^^^^^^^^^^^^^^^^^^^^^^^^^^^^^^^^^^^^^^^^\n",
            "  File \"/usr/local/lib/python3.11/dist-packages/aiogram/dispatcher/middlewares/error.py\", line 25, in __call__\n",
            "    return await handler(event, data)\n",
            "           ^^^^^^^^^^^^^^^^^^^^^^^^^^\n",
            "  File \"/usr/local/lib/python3.11/dist-packages/aiogram/dispatcher/middlewares/user_context.py\", line 56, in __call__\n",
            "    return await handler(event, data)\n",
            "           ^^^^^^^^^^^^^^^^^^^^^^^^^^\n",
            "  File \"/usr/local/lib/python3.11/dist-packages/aiogram/fsm/middleware.py\", line 42, in __call__\n",
            "    return await handler(event, data)\n",
            "           ^^^^^^^^^^^^^^^^^^^^^^^^^^\n",
            "  File \"/usr/local/lib/python3.11/dist-packages/aiogram/dispatcher/event/telegram.py\", line 121, in trigger\n",
            "    return await wrapped_inner(event, kwargs)\n",
            "           ^^^^^^^^^^^^^^^^^^^^^^^^^^^^^^^^^^\n",
            "  File \"/usr/local/lib/python3.11/dist-packages/aiogram/dispatcher/event/handler.py\", line 43, in call\n",
            "    return await wrapped()\n",
            "           ^^^^^^^^^^^^^^^\n",
            "  File \"/usr/local/lib/python3.11/dist-packages/aiogram/dispatcher/dispatcher.py\", line 276, in _listen_update\n",
            "    return await self.propagate_event(update_type=update_type, event=event, **kwargs)\n",
            "           ^^^^^^^^^^^^^^^^^^^^^^^^^^^^^^^^^^^^^^^^^^^^^^^^^^^^^^^^^^^^^^^^^^^^^^^^^^\n",
            "  File \"/usr/local/lib/python3.11/dist-packages/aiogram/dispatcher/router.py\", line 146, in propagate_event\n",
            "    return await observer.wrap_outer_middleware(_wrapped, event=event, data=kwargs)\n",
            "           ^^^^^^^^^^^^^^^^^^^^^^^^^^^^^^^^^^^^^^^^^^^^^^^^^^^^^^^^^^^^^^^^^^^^^^^^\n",
            "  File \"/usr/local/lib/python3.11/dist-packages/aiogram/dispatcher/router.py\", line 141, in _wrapped\n",
            "    return await self._propagate_event(\n",
            "           ^^^^^^^^^^^^^^^^^^^^^^^^^^^^\n",
            "  File \"/usr/local/lib/python3.11/dist-packages/aiogram/dispatcher/router.py\", line 166, in _propagate_event\n",
            "    response = await observer.trigger(event, **kwargs)\n",
            "               ^^^^^^^^^^^^^^^^^^^^^^^^^^^^^^^^^^^^^^^\n",
            "  File \"/usr/local/lib/python3.11/dist-packages/aiogram/dispatcher/event/telegram.py\", line 121, in trigger\n",
            "    return await wrapped_inner(event, kwargs)\n",
            "           ^^^^^^^^^^^^^^^^^^^^^^^^^^^^^^^^^^\n",
            "  File \"/usr/local/lib/python3.11/dist-packages/aiogram/dispatcher/event/handler.py\", line 43, in call\n",
            "    return await wrapped()\n",
            "           ^^^^^^^^^^^^^^^\n",
            "  File \"<ipython-input-9-d12a11f58cce>\", line 121, in echo\n",
            "    await message.answer(f\"Произошла ошибка: {str(e)}\")  # Исправлено: str(e) для корректного вывода ошибки\n",
            "    ^^^^^^^^^^^^^^^^^^^^^^^^^^^^^^^^^^^^^^^^^^^^^^^^^^^\n",
            "  File \"/usr/local/lib/python3.11/dist-packages/aiogram/methods/base.py\", line 84, in emit\n",
            "    return await bot(self)\n",
            "           ^^^^^^^^^^^^^^^\n",
            "  File \"/usr/local/lib/python3.11/dist-packages/aiogram/client/bot.py\", line 498, in __call__\n",
            "    return await self.session(self, method, timeout=request_timeout)\n",
            "           ^^^^^^^^^^^^^^^^^^^^^^^^^^^^^^^^^^^^^^^^^^^^^^^^^^^^^^^^^\n",
            "  File \"/usr/local/lib/python3.11/dist-packages/aiogram/client/session/base.py\", line 254, in __call__\n",
            "    return cast(TelegramType, await middleware(bot, method))\n",
            "                              ^^^^^^^^^^^^^^^^^^^^^^^^^^^^^\n",
            "  File \"/usr/local/lib/python3.11/dist-packages/aiogram/client/session/aiohttp.py\", line 185, in make_request\n",
            "    response = self.check_response(\n",
            "               ^^^^^^^^^^^^^^^^^^^^\n",
            "  File \"/usr/local/lib/python3.11/dist-packages/aiogram/client/session/base.py\", line 120, in check_response\n",
            "    raise TelegramBadRequest(method=method, message=description)\n",
            "aiogram.exceptions.TelegramBadRequest: Telegram server says - Bad Request: can't parse entities: Unsupported start tag \"_io.bufferedreader\" at byte offset 173\n"
          ]
        },
        {
          "output_type": "stream",
          "name": "stdout",
          "text": [
            "Аудиофайл создан.\n"
          ]
        },
        {
          "output_type": "stream",
          "name": "stderr",
          "text": [
            "/usr/local/lib/python3.11/dist-packages/transformers/generation/configuration_utils.py:628: UserWarning: `do_sample` is set to `False`. However, `temperature` is set to `0.7` -- this flag is only used in sample-based generation modes. You should set `do_sample=True` or unset `temperature`.\n",
            "  warnings.warn(\n",
            "/usr/local/lib/python3.11/dist-packages/transformers/generation/configuration_utils.py:633: UserWarning: `do_sample` is set to `False`. However, `top_p` is set to `0.95` -- this flag is only used in sample-based generation modes. You should set `do_sample=True` or unset `top_p`.\n",
            "  warnings.warn(\n",
            "ERROR:aiogram.event:Cause exception while process update id=995587232 by bot id=7954916275\n",
            "TelegramBadRequest: Telegram server says - Bad Request: can't parse entities: Unsupported start tag \"_io.bufferedreader\" at byte offset 173\n",
            "Traceback (most recent call last):\n",
            "  File \"<ipython-input-9-d12a11f58cce>\", line 106, in echo\n",
            "    await message.answer_audio(audio)\n",
            "          ^^^^^^^^^^^^^^^^^^^^^^^^^^^\n",
            "  File \"/usr/local/lib/python3.11/dist-packages/aiogram/types/message.py\", line 1022, in answer_audio\n",
            "    return SendAudio(\n",
            "           ^^^^^^^^^^\n",
            "  File \"/usr/local/lib/python3.11/dist-packages/pydantic/main.py\", line 214, in __init__\n",
            "    validated_self = self.__pydantic_validator__.validate_python(data, self_instance=self)\n",
            "                     ^^^^^^^^^^^^^^^^^^^^^^^^^^^^^^^^^^^^^^^^^^^^^^^^^^^^^^^^^^^^^^^^^^^^^\n",
            "pydantic_core._pydantic_core.ValidationError: 2 validation errors for SendAudio\n",
            "audio.is-instance[InputFile]\n",
            "  Input should be an instance of InputFile [type=is_instance_of, input_value=<_io.BufferedReader name='response.mp3'>, input_type=BufferedReader]\n",
            "    For further information visit https://errors.pydantic.dev/2.10/v/is_instance_of\n",
            "audio.str\n",
            "  Input should be a valid string [type=string_type, input_value=<_io.BufferedReader name='response.mp3'>, input_type=BufferedReader]\n",
            "    For further information visit https://errors.pydantic.dev/2.10/v/string_type\n",
            "\n",
            "During handling of the above exception, another exception occurred:\n",
            "\n",
            "Traceback (most recent call last):\n",
            "  File \"/usr/local/lib/python3.11/dist-packages/aiogram/dispatcher/dispatcher.py\", line 309, in _process_update\n",
            "    response = await self.feed_update(bot, update, **kwargs)\n",
            "               ^^^^^^^^^^^^^^^^^^^^^^^^^^^^^^^^^^^^^^^^^^^^^\n",
            "  File \"/usr/local/lib/python3.11/dist-packages/aiogram/dispatcher/dispatcher.py\", line 158, in feed_update\n",
            "    response = await self.update.wrap_outer_middleware(\n",
            "               ^^^^^^^^^^^^^^^^^^^^^^^^^^^^^^^^^^^^^^^^\n",
            "  File \"/usr/local/lib/python3.11/dist-packages/aiogram/dispatcher/middlewares/error.py\", line 25, in __call__\n",
            "    return await handler(event, data)\n",
            "           ^^^^^^^^^^^^^^^^^^^^^^^^^^\n",
            "  File \"/usr/local/lib/python3.11/dist-packages/aiogram/dispatcher/middlewares/user_context.py\", line 56, in __call__\n",
            "    return await handler(event, data)\n",
            "           ^^^^^^^^^^^^^^^^^^^^^^^^^^\n",
            "  File \"/usr/local/lib/python3.11/dist-packages/aiogram/fsm/middleware.py\", line 42, in __call__\n",
            "    return await handler(event, data)\n",
            "           ^^^^^^^^^^^^^^^^^^^^^^^^^^\n",
            "  File \"/usr/local/lib/python3.11/dist-packages/aiogram/dispatcher/event/telegram.py\", line 121, in trigger\n",
            "    return await wrapped_inner(event, kwargs)\n",
            "           ^^^^^^^^^^^^^^^^^^^^^^^^^^^^^^^^^^\n",
            "  File \"/usr/local/lib/python3.11/dist-packages/aiogram/dispatcher/event/handler.py\", line 43, in call\n",
            "    return await wrapped()\n",
            "           ^^^^^^^^^^^^^^^\n",
            "  File \"/usr/local/lib/python3.11/dist-packages/aiogram/dispatcher/dispatcher.py\", line 276, in _listen_update\n",
            "    return await self.propagate_event(update_type=update_type, event=event, **kwargs)\n",
            "           ^^^^^^^^^^^^^^^^^^^^^^^^^^^^^^^^^^^^^^^^^^^^^^^^^^^^^^^^^^^^^^^^^^^^^^^^^^\n",
            "  File \"/usr/local/lib/python3.11/dist-packages/aiogram/dispatcher/router.py\", line 146, in propagate_event\n",
            "    return await observer.wrap_outer_middleware(_wrapped, event=event, data=kwargs)\n",
            "           ^^^^^^^^^^^^^^^^^^^^^^^^^^^^^^^^^^^^^^^^^^^^^^^^^^^^^^^^^^^^^^^^^^^^^^^^\n",
            "  File \"/usr/local/lib/python3.11/dist-packages/aiogram/dispatcher/router.py\", line 141, in _wrapped\n",
            "    return await self._propagate_event(\n",
            "           ^^^^^^^^^^^^^^^^^^^^^^^^^^^^\n",
            "  File \"/usr/local/lib/python3.11/dist-packages/aiogram/dispatcher/router.py\", line 166, in _propagate_event\n",
            "    response = await observer.trigger(event, **kwargs)\n",
            "               ^^^^^^^^^^^^^^^^^^^^^^^^^^^^^^^^^^^^^^^\n",
            "  File \"/usr/local/lib/python3.11/dist-packages/aiogram/dispatcher/event/telegram.py\", line 121, in trigger\n",
            "    return await wrapped_inner(event, kwargs)\n",
            "           ^^^^^^^^^^^^^^^^^^^^^^^^^^^^^^^^^^\n",
            "  File \"/usr/local/lib/python3.11/dist-packages/aiogram/dispatcher/event/handler.py\", line 43, in call\n",
            "    return await wrapped()\n",
            "           ^^^^^^^^^^^^^^^\n",
            "  File \"<ipython-input-9-d12a11f58cce>\", line 121, in echo\n",
            "    await message.answer(f\"Произошла ошибка: {str(e)}\")  # Исправлено: str(e) для корректного вывода ошибки\n",
            "    ^^^^^^^^^^^^^^^^^^^^^^^^^^^^^^^^^^^^^^^^^^^^^^^^^^^\n",
            "  File \"/usr/local/lib/python3.11/dist-packages/aiogram/methods/base.py\", line 84, in emit\n",
            "    return await bot(self)\n",
            "           ^^^^^^^^^^^^^^^\n",
            "  File \"/usr/local/lib/python3.11/dist-packages/aiogram/client/bot.py\", line 498, in __call__\n",
            "    return await self.session(self, method, timeout=request_timeout)\n",
            "           ^^^^^^^^^^^^^^^^^^^^^^^^^^^^^^^^^^^^^^^^^^^^^^^^^^^^^^^^^\n",
            "  File \"/usr/local/lib/python3.11/dist-packages/aiogram/client/session/base.py\", line 254, in __call__\n",
            "    return cast(TelegramType, await middleware(bot, method))\n",
            "                              ^^^^^^^^^^^^^^^^^^^^^^^^^^^^^\n",
            "  File \"/usr/local/lib/python3.11/dist-packages/aiogram/client/session/aiohttp.py\", line 185, in make_request\n",
            "    response = self.check_response(\n",
            "               ^^^^^^^^^^^^^^^^^^^^\n",
            "  File \"/usr/local/lib/python3.11/dist-packages/aiogram/client/session/base.py\", line 120, in check_response\n",
            "    raise TelegramBadRequest(method=method, message=description)\n",
            "aiogram.exceptions.TelegramBadRequest: Telegram server says - Bad Request: can't parse entities: Unsupported start tag \"_io.bufferedreader\" at byte offset 173\n"
          ]
        },
        {
          "output_type": "stream",
          "name": "stdout",
          "text": [
            "Аудиофайл создан.\n"
          ]
        },
        {
          "output_type": "stream",
          "name": "stderr",
          "text": [
            "WARNING:aiogram.dispatcher:Received SIGINT signal\n"
          ]
        }
      ]
    }
  ]
}